Workbook

Sheet สินค้าBB
D1: ระดับราคา | F1: 20%-50%
A2: รหัสสินค้า | B2: ราคาส่ง | C2: ค่าลับคม | D2: ราคา+10% | E2: ราคา+15% | F2: ราคาปลีกออนไลน์
A3: BB-516 | B3: 150 | D3: =MROUND((B3*10%)+B3,5) -> 165 | E3: =MROUND((B3*15%)+B3,5) -> 175 | F3: 199 | G3: =(F3-B3)/B3 -> 0.32666667 | H3: =F3-D3 -> 34 | I3: =F3-E3 -> 24
A4: BB-511 | B4: 165 | D4: =MROUND((B4*10%)+B4,5) -> 180 | E4: =MROUND((B4*15%)+B4,5) -> 190 | F4: 240 | G4: =(F4-B4)/B4 -> 0.45454545 | H4: =F4-D4 -> 60 | I4: =F4-E4 -> 50
A5: BB-503 | B5: 150 | D5: =MROUND((B5*10%)+B5,5) -> 165 | E5: =MROUND((B5*15%)+B5,5) -> 175 | F5: 240 | G5: =(F5-B5)/B5 -> 0.6 | H5: =F5-D5 -> 75 | I5: =F5-E5 -> 65
A6: BB-507 | B6: 230 | D6: 235 | E6: =MROUND((B6*15%)+B6,5) -> 265 | F6: 240 | G6: =(F6-B6)/B6 -> 0.043478261 | H6: =F6-D6 -> 5 | I6: =F6-E6 -> -25
A7: BB-509 | B7: 170 | D7: =MROUND((B7*10%)+B7,5) -> 185 | E7: =MROUND((B7*15%)+B7,5) -> 195 | F7: 240 | G7: =(F7-B7)/B7 -> 0.41176471 | H7: =F7-D7 -> 55 | I7: =F7-E7 -> 45
A8: BB-702 | B8: 165 | D8: =MROUND((B8*10%)+B8,5) -> 180 | E8: =MROUND((B8*15%)+B8,5) -> 190 | F8: 199 | G8: =(F8-B8)/B8 -> 0.20606061 | H8: =F8-D8 -> 19 | I8: =F8-E8 -> 9
A9: BB-517 | B9: 120 | D9: =MROUND((B9*10%)+B9,5) -> 130 | E9: =MROUND((B9*15%)+B9,5) -> 140 | F9: 165 | G9: =(F9-B9)/B9 -> 0.375 | H9: =F9-D9 -> 35 | I9: =F9-E9 -> 25
A10: BB-510 | B10: 110 | D10: =MROUND((B10*10%)+B10,5) -> 120 | E10: =MROUND((B10*15%)+B10,5) -> 125 | F10: 150 | G10: =(F10-B10)/B10 -> 0.36363636 | H10: =F10-D10 -> 30 | I10: =F10-E10 -> 25
A11: BB-512 | B11: 170 | D11: =MROUND((B11*10%)+B11,5) -> 185 | E11: =MROUND((B11*15%)+B11,5) -> 195 | F11: 250 | G11: =(F11-B11)/B11 -> 0.47058824 | H11: =F11-D11 -> 65 | I11: =F11-E11 -> 55
A12: BB-513 | B12: 140 | D12: =MROUND((B12*10%)+B12,5) -> 155 | E12: =MROUND((B12*15%)+B12,5) -> 160 | F12: 190 | G12: =(F12-B12)/B12 -> 0.35714286 | H12: =F12-D12 -> 35 | I12: =F12-E12 -> 30
A13: BB-703 | B13: 125 | D13: =MROUND((B13*10%)+B13,5) -> 140 | E13: =MROUND((B13*15%)+B13,5) -> 145 | F13: 250 | G13: =(F13-B13)/B13 -> 1 | H13: =F13-D13 -> 110 | I13: =F13-E13 -> 105
A14: BB-704 | B14: 25 | D14: =MROUND((B14*10%)+B14,5) -> 30 | E14: =MROUND((B14*15%)+B14,5) -> 30 | F14: 50 | G14: =(F14-B14)/B14 -> 1 | H14: =F14-D14 -> 20 | I14: =F14-E14 -> 20
A15: BB-514 | B15: 120 | D15: =MROUND((B15*10%)+B15,5) -> 130 | E15: =MROUND((B15*15%)+B15,5) -> 140 | F15: 240 | G15: =(F15-B15)/B15 -> 1 | H15: =F15-D15 -> 110 | I15: =F15-E15 -> 100
A16: BB-515 | B16: 170 | D16: =MROUND((B16*10%)+B16,5) -> 185 | E16: =MROUND((B16*15%)+B16,5) -> 195 | F16: 250 | G16: =(F16-B16)/B16 -> 0.47058824 | H16: =F16-D16 -> 65 | I16: =F16-E16 -> 55
A17: BB-111 | B17: 1350 | D17: =MROUND((B17*10%)+B17,5) -> 1485 | E17: =MROUND((B17*15%)+B17,5) -> 1555 | F17: 1950 | G17: =(F17-B17)/B17 -> 0.44444444 | H17: =F17-D17 -> 465 | I17: =F17-E17 -> 395
A18: BB-112 | B18: 1000 | D18: =MROUND((B18*10%)+B18,5) -> 1100 | E18: =MROUND((B18*15%)+B18,5) -> 1150 | F18: 1350 | G18: =(F18-B18)/B18 -> 0.35 | H18: =F18-D18 -> 250 | I18: =F18-E18 -> 200
... A20: BB-110 | B20: 1050 | D20: =MROUND((B20*10%)+B20,5) -> 1155 | E20: =MROUND((B20*15%)+B20,5) -> 1210 | F20: 1500 | G20: =(F20-B20)/B20 -> 0.42857143 | H20: =F20-D20 -> 345 | I20: =F20-E20 -> 290
A21: BB-100 | B21: 420 | C21: 65 | D21: =MROUND((B21*10%)+B21,5) -> 460 | E21: =MROUND((B21*15%)+B21,5) -> 485 | F21: 750 | G21: =(F21-B21)/B21 -> 0.78571429 | H21: =F21-D21 -> 290 | I21: =F21-E21 -> 265
A22: BB-103 | B22: 75 | D22: =MROUND((B22*10%)+B22,5) -> 85 | E22: =MROUND((B22*15%)+B22,5) -> 85 | F22: 200 | G22: =(F22-B22)/B22 -> 1.6666667 | H22: =F22-D22 -> 115 | I22: =F22-E22 -> 115
A23: BB-103/A | B23: 38 | D23: =MROUND((B23*10%)+B23,5) -> 40 | E23: =MROUND((B23*15%)+B23,5) -> 45 | F23: 150 | G23: =(F23-B23)/B23 -> 2.9473684 | H23: =F23-D23 -> 110 | I23: =F23-E23 -> 105
A24: BB-104 | B24: 140 | D24: =MROUND((B24*10%)+B24,5) -> 155 | E24: =MROUND((B24*15%)+B24,5) -> 160 | F24: 250 | G24: =(F24-B24)/B24 -> 0.78571429 | H24: =F24-D24 -> 95 | I24: =F24-E24 -> 90
A25: ZM-BB-111/4 | B25: 210 | D25: =MROUND((B25*10%)+B25,5) -> 230 | E25: =MROUND((B25*15%)+B25,5) -> 240 | F25: 300 | G25: =(F25-B25)/B25 -> 0.42857143 | H25: =F25-D25 -> 70 | I25: =F25-E25 -> 60
A26: VAL-64 | B26: 315 | D26: =MROUND((B26*10%)+B26,5) -> 345 | E26: =MROUND((B26*15%)+B26,5) -> 360 | F26: 450 | G26: =(F26-B26)/B26 -> 0.42857143 | H26: =F26-D26 -> 105 | I26: =F26-E26 -> 90
A27: VAL-65 | B27: 325 | D27: =MROUND((B27*10%)+B27,5) -> 360 | E27: =MROUND((B27*15%)+B27,5) -> 375 | F27: 450 | G27: =(F27-B27)/B27 -> 0.38461538 | H27: =F27-D27 -> 90 | I27: =F27-E27 -> 75
A28: VAL-66 | B28: 320 | D28: =MROUND((B28*10%)+B28,5) -> 350 | E28: =MROUND((B28*15%)+B28,5) -> 370 | F28: 450 | G28: =(F28-B28)/B28 -> 0.40625 | H28: =F28-D28 -> 100 | I28: =F28-E28 -> 80
A29: VAL-67 | B29: 320 | D29: =MROUND((B29*10%)+B29,5) -> 350 | E29: =MROUND((B29*15%)+B29,5) -> 370 | F29: 450 | G29: =(F29-B29)/B29 -> 0.40625 | H29: =F29-D29 -> 100 | I29: =F29-E29 -> 80
A30: VAL-73 | B30: 315 | D30: =MROUND((B30*10%)+B30,5) -> 345 | E30: =MROUND((B30*15%)+B30,5) -> 360 | F30: 450 | G30: =(F30-B30)/B30 -> 0.42857143 | H30: =F30-D30 -> 105 | I30: =F30-E30 -> 90
A31: VAL-74 | B31: 325 | D31: =MROUND((B31*10%)+B31,5) -> 360 | E31: =MROUND((B31*15%)+B31,5) -> 375 | F31: 450 | G31: =(F31-B31)/B31 -> 0.38461538 | H31: =F31-D31 -> 90 | I31: =F31-E31 -> 75
A32: ZP-A16015 | B32: 400 | D32: 425 | E32: 430 | F32: 435 | G32: =(F32-B32)/B32 -> 0.0875 | H32: =F32-D32 -> 10 | I32: =F32-E32 -> 5
A33: VAL-1516 | B33: 150 | D33: =MROUND((B33*10%)+B33,5) -> 165 | E33: =MROUND((B33*15%)+B33,5) -> 175 | F33: 190 | G33: =(F33-B33)/B33 -> 0.26666667 | H33: =F33-D33 -> 25 | I33: =F33-E33 -> 15
A34: VAL-K099 | B34: 135 | D34: =MROUND((B34*10%)+B34,5) -> 150 | E34: =MROUND((B34*15%)+B34,5) -> 155 | F34: 200 | G34: =(F34-B34)/B34 -> 0.48148148 | H34: =F34-D34 -> 50 | I34: =F34-E34 -> 45
A35: VAL-K024 | B35: 200 | D35: =MROUND((B35*10%)+B35,5) -> 220 | E35: =MROUND((B35*15%)+B35,5) -> 230 | F35: 250 | G35: =(F35-B35)/B35 -> 0.25 | H35: =F35-D35 -> 30 | I35: =F35-E35 -> 20
A36: VAL-1513 | B36: 150 | D36: =MROUND((B36*10%)+B36,5) -> 165 | E36: =MROUND((B36*15%)+B36,5) -> 175 | F36: 190 | G36: =(F36-B36)/B36 -> 0.26666667 | H36: =F36-D36 -> 25 | I36: =F36-E36 -> 15
A37: VAL-1510/W-1 | B37: 84 | D37: =MROUND((B37*10%)+B37,5) -> 90 | E37: =MROUND((B37*15%)+B37,5) -> 95 | F37: 120 | G37: =(F37-B37)/B37 -> 0.42857143 | H37: =F37-D37 -> 30 | I37: =F37-E37 -> 25
A38: VAL-1510/W | B38: 87.08 | D38: =MROUND((B38*10%)+B38,5) -> 95 | E38: =MROUND((B38*15%)+B38,5) -> 100 | F38: 120 | G38: =(F38-B38)/B38 -> 0.37804318 | H38: =F38-D38 -> 25 | I38: =F38-E38 -> 20
A39: VAL-1510/B-1 | B39: 84 | D39: =MROUND((B39*10%)+B39,5) -> 90 | E39: =MROUND((B39*15%)+B39,5) -> 95 | F39: 120 | G39: =(F39-B39)/B39 -> 0.42857143 | H39: =F39-D39 -> 30 | I39: =F39-E39 -> 25
A40: VAL-1510/B | B40: 87.08 | D40: =MROUND((B40*10%)+B40,5) -> 95 | E40: =MROUND((B40*15%)+B40,5) -> 100 | F40: 120 | G40: =(F40-B40)/B40 -> 0.37804318 | H40: =F40-D40 -> 25 | I40: =F40-E40 -> 20
A41: VAL-1511 | B41: 154 | D41: =MROUND((B41*10%)+B41,5) -> 170 | E41: =MROUND((B41*15%)+B41,5) -> 175 | F41: 195 | G41: =(F41-B41)/B41 -> 0.26623377 | H41: =F41-D41 -> 25 | I41: =F41-E41 -> 20
...

Sheet Checklist-Tech
G1: Note
A2: priority | B2: สถานะ | C2: ประเภทสินค้า | D2: รหัสสินค้า | E2: ชื่อ | F2: ปริมาณสินค้า | G2: ปริมาณต่อหัว (1ขวดได้กี่หัว / ถ้าสี1หัวใช้กี่หลอด) | J2: เทคนิคเพิ่มเติมในการขาย | K2: ทรงผม
G3: S | H3: M | I3: L
A4: 1 | B4: สินค้าใหม่ | C4: ทรีทเมนท์ | D4: MRP-C12-1 | E4: MaxRepeat C12 Anti-Breakage Strengthening Magic Keratin Shampoo No.1 แชมพูเบอร์ 1 ขนาด 400 ml | F4: 400ml. | G4: 4 pump , 5 ml / 80 times | H4: 6 pump , 7.5 ml / 53 times | I4: 8 ml / 10 times / 40 times
A5: 1 | B5: สินค้าใหม่ | C5: ทรีทเมนท์ | D5: MRP-C12-2 | E5: MaxRepeat C12 Anti-Breakage Strengthening Magic Keratin Serum No.2 เซรั่มเบอร์ 2 ขนาด 230 ml | F5: 230ml. | G5: 10 ml / 23 times | H5: 15 ml / 15 times | I5: 15 ml / 15 times
A6: 1 | B6: สินค้าใหม่ | C6: ทรีทเมนท์ | D6: MRP-C12-3 | E6: MaxRepeat C12 Anti-Breakage Magic Keratin Serum No.3 เซรั่มเบอร์ 3 ขนาด 230 ml | F6: 230ml. | G6: 10 ml / 23 times | H6: 15 ml / 15 times | I6: 15 ml / 15 times
A7: 1 | B7: สินค้าใหม่ | C7: ทรีทเมนท์ | D7: MRP-C12-4 | E7: MaxRepeat C12 Anti-Breakage Fortifying Magic Keratin Fortifying Mask No.4 มาสก์เบอร์ 4 ขนาด 400 ml | F7: 400ml. | G7: 4 pump , 5 ml / 80 times | H7: 6 pump , 7.5 ml / 53 times | I7: 8 ml / 10 times / 40 times
A8: 1 | B8: สินค้าใหม่ | C8: ทรีทเมนท์ | D8: MRP-C12S-2 | E8: MaxRepeat C12 Anti-Breakage Magic Keratin System Set No.2 & No.3 เซตกล่อง เบอร์ 1 และ เบอร์ 2 | F8: 25mlx10 | G8: 10 ml. / 2 times | H8: 10 ml. / 2 times | I8: 10 ml. / 2 times
A9: 2 | B9: สินค้าใหม่ | C9: ทรีทเมนท์ | D9: BB-201 | E9: BARBER BRAIN ANAGAIN HAIR SHAMPOO 250ml บาร์เบอร์เบรน อนาเกน แฮร์ แชมพู | F9: 250ml. | G9: 2 pump , 4 ml / 75 times | H9: 4 pump , 8 ml / 60 times | I9: 6 pump , 10 ml / 25 times
A10: 2 | B10: สินค้าใหม่ | C10: ทรีทเมนท์ | D10: BB-202 | E10: BARBER BRAIN ANAGAIN HAIR CONDITION 250mlบาร์เบอร์เบรน อนาเกน แฮร์ คอนดิชั่นเนอร์ | F10: 250ml. | G10: 5 pump , 7.5 ml / 33 times | H10: 5 pump , 7.5 ml / 33 times | I10: 5 pump , 7.5 ml / 33 times
A11: 2 | B11: สินค้าใหม่ | C11: ทรีทเมนท์ | D11: BB-203 | E11: BARBER BRAIN ANAGAIN HAIR TONIC 120ml บาร์เบอร์เบรน อนาเกน แฮร์ โทนิค | F11: 120ml. | G11: 10 pump , 1 ml / 120 times | H11: 10 pump , 1 ml / 120 times | I11: 10 pump , 1 ml / 120 times
A12: 2 | B12: สินค้าใหม่ | C12: ทรีทเมนท์ | D12: BB-204 | E12: BARBER BRAIN NO GREY HAIR SHAMPOO 250ml บาร์เบอร์เบรน โน เกร แฮร์ แชมพู | F12: 250ml. | G12: 2 pump , 4 ml / 75 times | H12: 4 pump , 8 ml / 60 times | I12: 6 pump , 10 ml / 25 times
A13: 2 | B13: สินค้าใหม่ | C13: ทรีทเมนท์ | D13: BB-205 | E13: BARBER BRAIN NO GREY HAIR CONDITION 250ml บาร์เบอร์เบรน โน เกร แฮร์ คอนดิชั่นเนอร์ | F13: 250ml. | G13: 5 pump , 7.5 ml / 33 times | H13: 5 pump , 7.5 ml / 33 times | I13: 5 pump , 7.5 ml / 33 times
A14: 2 | B14: สินค้าใหม่ | C14: ทรีทเมนท์ | D14: BB-206 | E14: BARBER BRAIN NO GREY HAIR TONIC 120ml บาร์เบอร์เบรน โน เกร แฮร์ โทนิค | F14: 120ml. | G14: 10 pump , 1 ml / 120 times | H14: 10 pump , 1 ml / 120 times | I14: 10 pump , 1 ml / 120 times
A15: 3 | C15: เคมีภัณฑ์-ผงฟอก | D15: ANG-067 | E15: L’ANGEL Hair Bleaching Powder Gentle Blonde 60gx12 ผงฟอกสีผม | F15: 60gx12 | G15: 4 x 60 = 240 g. / 1 time | H15: 6 x 60 = 360 g. / 1 time | I15: 8 x 60 = 480 g. / 1 time
A16: 3 | C16: เคมีภัณฑ์-ผงฟอก | D16: ANG-066 | E16: L'ANGEL HAIR BLEACHING POWDER ผลิตภัณฑ์ฟอกสีผม ANG-066 | F16: 500g | G16: 250 g / 1 times | H16: 350 g / 1 times | I16: 450 g / 1 times
A17: 3 | C17: เคมีภัณฑ์-ผงฟอก | D17: ANG-069 | E17: L'ANGEL LUXURY ANGELIC 9 LEVELS แอลแองเจล ผงฟอกสีผม 400g ANG-069 | F17: 400g | G17: 250 g / 1 times | H17: 350 g / 1 times | I17: 450 g / 1 times
A18: 4 | C18: เคมีภัณฑ์-สีผม | D18: Infinity | E18: L'ANGEL Infinity Hair Colors PRO | F18: 100mlx2 | G18: 100-150 ml. | H18: 250-300 ml. | I18: 300-400 ml.
A19: 4 | C19: เคมีภัณฑ์-สีผม | D19: Monetti | E19: สีย้อมผมถาวร | F19: 80ml. | G19: 100-160 ml. | H19: 240-320 ml. | I19: 320-400 ml.
A20: 4 | C20: เคมีภัณฑ์-น้ำยาดัด | D20: BB-703 | E20: ชุดน้ำยาดัดเย็นสูตรเนื้อเจล Energy Perm ปริมาณ 150ml. (01น้ำยาดัด , 02น้ำยาโกรก) | F20: 150ml.x2
E21: Down Prem | G21: 25 g. / 6 times | H21: 25 g. / 6 times | I21: 25 g. / 6 times
E22: Up Prem | G22: 10 g. / 15 times | H22: 10 g. / 15 times | I22: 10 g. / 15 times
E23: American Perm | G23: 70 g. / 2 times | H23: 100g. / 1 times | I23: 100g. / 1 times
E24: Volome Perm | G24: 70 g. / 2 times | H24: 100 g. / 1 times | I24: 100g. / 1 times
E25: Foil Perm | G25: 50 g. / 3 times | H25: 75 g. / 2 times | I25: 75 g. / 2 times
E26: Titanium Perm | G26: 75 g. / 2 times | H26: 100 g. / 1 times | I26: 75 g. / 2 times
E27: Wire Perm | G27: 75 g. / 2 times | H27: 75 g. / 2 times | I27: 75 g. / 2 times
E28: Pin Prem | G28: 75 g. / 2 times | H28: 75 g. / 2 times | I28: 75 g. / 2 times
A29: 4 | C29: เคมีภัณฑ์-น้ำยาดัด | D29: BB-704 | E29: ผงผสมน้ำยาดัดเย็น Down Perm ปริมาณ 100g ( | F29: 100g
E30: BB-703 No.1 : BB-704 (2:1) (Powder ใช้เท่าเดิม ปริมาณ No.1 ขึ้นอยู่กับสูตร) | G30: 20 : 10 g. / 10 times | H30: 20 : 10 g. / 10 times | I30: 20 : 10 g. / 10 times
E31: BB-703 No.1 : BB-704 (3:1) (Powder ใช้เท่าเดิม ปริมาณ No.1 ขึ้นอยู่กับสูตร) | G31: 30 : 10 g. / 10 times | H31: 30 : 10 g. / 10 times | I31: 30 : 10 g. / 10 times
A32: 5 | C32: เคมีภัณฑ์-เชื่อมแกน | D32: ANG-410 | E32: L'ANGEL Bond Creator บอนด์ ครีเอเตอร์ โปรเฟสชั่นนอล ซาลอน คิต ปริมาณ 300x3มล. ANG-410 | F32: 300mlx3
E33: Bleaching (1:10) | G33: 25 ml | H33: 35 ml | I33: 45 ml
E34: Hair Color 1:10) | G34: 10-15 ml | H34: 25-30 ml | I34: 30-40 ml
E35: Treament (1:10) | G35: 4 ml | H35: 6 ml | I35: 8 ml
A36: 5 | C36: เคมีภัณฑ์-เคราติน | D36: ANG-613 | E36: L'ANGEL SMART KERATIN แอลแองเจล สมาร์ท เคราติน แชมพู+ทรีทเมนต์ 258 ml.x2 รุ่น ANG-613 | F36: 258ml.x2 | G36: 40 g. / 6 times | H36: 60 g. / 4 times | I36: 80 g. / 3 times
A37: 5 | C37: เคมีภัณฑ์-น้ำยายืด | D37: ANG-109 | E37: L'ANGEL แอลแองเจล ชุดครีมยืดผมถาวร สูตรชาเขียว สำหรับผมไม่เคยทำเคมี ANG-109 | F37: 600ml | G37: 100 g. / 6 times | H37: 150 g. / 4 times | I37: 200 g. / 3 times
A38: 5 | C38: เคมีภัณฑ์-น้ำยายืด | D38: ANG-110 | E38: L'ANGEL แอลแองเจล ชุดครีมยืดผมถาวร สูตรอโรม่า สำหรับผมที่ผ่านการทำเคมีมาก่อน ANG-110 | F38: 600ml | G38: 100 g. / 6 times | H38: 150 g. / 4 times | I38: 200 g. / 3 times
A39: 5 | C39: ทรีทเมนท์ | D39: ANG-608 | E39: L'ANGEL Perfect Keratin เพอร์เฟ็ค เคราติน แชมพู+ครีมนวด 258ml.x2 กล่องขาว ANG-608 | F39: 258ml.x2
E40: Shampoo | G40: 10 g. / 25 times | H40: 15 g. / 25 times | I40: 20 g. / 13 times
...

Sheet PD-Master
L1: ระดับราคา
A2: รหัสสินค้า | B2: แบรนด์ | C2: ประเภทสินค้า | D2: ชื่อสินค้า (TH) | E2: จุดเด่นสินค้า | F2: 1 ลังมีกี่ชิ้น | G2: Barcode | H2: อย | I2: มอก | J2: น้ำหนัก+นนกล่อง (กรัม) | K2: ขนาด กxยxส | L2: ราคาส่ง | M2: ราคา+10% | N2: ราคาปลีกออนไลน์ | O2: ค่าแพคกิ้ง | P2: ค่าลับคม | Q2: ค่าฝา
A3: BB-516 | B3: Barber Brain (บาร์เบอร์ เบรน) | C3: =IFERROR(VLOOKUP(A3,data!A:G,7,FALSE),"") -> Grooming - ผลิตภัณพ์จัดแต่งทรงผมและหนวด | D3: =IFERROR(VLOOKUP(A3,data!A:D,4,FALSE),"") -> Barber Brain Prime Hair Spray สเปรย์น้ำนมกันความร้อน สร้างวอลลุ่มยกโคนผม | G3: =IFERROR(VLOOKUP(A3,data!A:V,22,FALSE),"") -> 8858890800420 | J3: =IFERROR(VLOOKUP(A3,'dataนน'!A:F,6,FALSE),"") | K3: =IFERROR(VLOOKUP(A3,'dataนน'!A:G,7,FALSE),"") | L3: 150 | M3: 165 | N3: 199 | O3: 10 | Q3: =IFERROR(VLOOKUP(A3,'data-ค่าฝา'!B:G,6,FALSE),"")
A4: BB-511 | B4: Barber Brain (บาร์เบอร์ เบรน) | C4: =IFERROR(VLOOKUP(A4,data!A:G,7,FALSE),"") -> Grooming - ผลิตภัณพ์จัดแต่งทรงผมและหนวด | D4: =IFERROR(VLOOKUP(A4,data!A:D,4,FALSE),"") -> Barber Brain x Haris Styling Curl Control Cream for men ผลิตภัณฑ์จัดแต่งทรงผม 150 ml. รหัสสินค้า BB-511 | G4: =IFERROR(VLOOKUP(A4,data!A:V,22,FALSE),"") -> 8858890732486 | J4: =IFERROR(VLOOKUP(A4,'dataนน'!A:F,6,FALSE),"") | K4: =IFERROR(VLOOKUP(A4,'dataนน'!A:G,7,FALSE),"") | L4: 165 | M4: 180 | N4: 240 | O4: 10 | Q4: =IFERROR(VLOOKUP(A4,'data-ค่าฝา'!B:G,6,FALSE),"")
A5: BB-503 | B5: Barber Brain (บาร์เบอร์ เบรน) | C5: =IFERROR(VLOOKUP(A5,data!A:G,7,FALSE),"") -> Grooming - ผลิตภัณพ์จัดแต่งทรงผมและหนวด | D5: =IFERROR(VLOOKUP(A5,data!A:D,4,FALSE),"") -> บาร์เบอร์ เบรน ผลิตภัณฑ์จัดแต่งทรงผม โพเมด สูตรเงา รุ่น BB-503 | F5: 36 | G5: =IFERROR(VLOOKUP(A5,data!A:V,22,FALSE),"") -> 8858890715038 | J5: =IFERROR(VLOOKUP(A5,'dataนน'!A:F,6,FALSE),"") -> 0.171 | K5: =IFERROR(VLOOKUP(A5,'dataนน'!A:G,7,FALSE),"") -> 80 กรัม | L5: 150 | M5: 165 | N5: 240 | O5: 10 | Q5: =IFERROR(VLOOKUP(A5,'data-ค่าฝา'!B:G,6,FALSE),"") -> 10
A6: BB-507 | B6: Barber Brain (บาร์เบอร์ เบรน) | C6: =IFERROR(VLOOKUP(A6,data!A:G,7,FALSE),"") -> Grooming - ผลิตภัณพ์จัดแต่งทรงผมและหนวด | D6: =IFERROR(VLOOKUP(A6,data!A:D,4,FALSE),"") -> บาร์เบอร์ เบรน ผลิตภัณฑ์จัดแต่งทรงผม โพเมด สูตรแข็ง BB-507 | F6: 36 | G6: =IFERROR(VLOOKUP(A6,data!A:V,22,FALSE),"") -> 8858890715076 | J6: =IFERROR(VLOOKUP(A6,'dataนน'!A:F,6,FALSE),"") -> 0.171 | K6: =IFERROR(VLOOKUP(A6,'dataนน'!A:G,7,FALSE),"") -> 80 กรัม | L6: 230 | M6: 235 | N6: 240 | O6: 10 | Q6: =IFERROR(VLOOKUP(A6,'data-ค่าฝา'!B:G,6,FALSE),"") -> 15
A7: BB-509 | B7: Barber Brain (บาร์เบอร์ เบรน) | C7: =IFERROR(VLOOKUP(A7,data!A:G,7,FALSE),"") -> Grooming - ผลิตภัณพ์จัดแต่งทรงผมและหนวด | D7: =IFERROR(VLOOKUP(A7,data!A:D,4,FALSE),"") -> บาร์เบอร์ เบรน ผลิตภัณฑ์จัดแต่งทรงผม แฮร์ แว๊กซ์ รุ่น BB-509 | F7: 36 | G7: =IFERROR(VLOOKUP(A7,data!A:V,22,FALSE),"") -> 8858890715090 | J7: =IFERROR(VLOOKUP(A7,'dataนน'!A:F,6,FALSE),"") -> 0.176 | K7: =IFERROR(VLOOKUP(A7,'dataนน'!A:G,7,FALSE),"") -> 80 กรัม | L7: 170 | M7: 185 | N7: 240 | O7: 10 | Q7: =IFERROR(VLOOKUP(A7,'data-ค่าฝา'!B:G,6,FALSE),"") -> 10
A8: BB-702 | B8: Barber Brain (บาร์เบอร์ เบรน) | C8: =IFERROR(VLOOKUP(A8,data!A:G,7,FALSE),"") -> Grooming - ผลิตภัณพ์จัดแต่งทรงผมและหนวด | D8: =IFERROR(VLOOKUP(A8,data!A:D,4,FALSE),"") -> บาร์เบอร์ เบรน เท็คเจอร์ & วอลลุ่ม แฮร์ สเปรย์ BB-702 | F8: 48 | G8: =IFERROR(VLOOKUP(A8,data!A:V,22,FALSE),"") -> 8858890717025 | J8: =IFERROR(VLOOKUP(A8,'dataนน'!A:F,6,FALSE),"") -> 0.296 | K8: =IFERROR(VLOOKUP(A8,'dataนน'!A:G,7,FALSE),"") -> 200 ml | L8: 165 | M8: 180 | N8: 199 | O8: 10 | Q8: =IFERROR(VLOOKUP(A8,'data-ค่าฝา'!B:G,6,FALSE),"") -> 10
A9: BB-517 | B9: Barber Brain (บาร์เบอร์ เบรน) | C9: =IFERROR(VLOOKUP(A9,data!A:G,7,FALSE),"") -> Grooming - ผลิตภัณพ์จัดแต่งทรงผมและหนวด | D9: =IFERROR(VLOOKUP(A9,data!A:D,4,FALSE),"") -> BB-517 บาร์เบอร์เบรน ดัสท์ พาวเดอร์ 4g สเปรย์ชนิดแป้งยกโคนผม | G9: =IFERROR(VLOOKUP(A9,data!A:V,22,FALSE),"") -> 8858890798802 | J9: =IFERROR(VLOOKUP(A9,'dataนน'!A:F,6,FALSE),"") | K9: =IFERROR(VLOOKUP(A9,'dataนน'!A:G,7,FALSE),"") | L9: 120 | M9: 130 | N9: 165 | O9: 10 | Q9: =IFERROR(VLOOKUP(A9,'data-ค่าฝา'!B:G,6,FALSE),"") -> 5
A10: BB-510 | B10: Barber Brain (บาร์เบอร์ เบรน) | C10: =IFERROR(VLOOKUP(A10,data!A:G,7,FALSE),"") -> Grooming - ผลิตภัณพ์จัดแต่งทรงผมและหนวด | D10: =IFERROR(VLOOKUP(A10,data!A:D,4,FALSE),"") -> BB-510 บาร์เบอร์เบรน ซิลเวอร์ เบลด เซฟ เจล ปริมาณ 140ml. | G10: =IFERROR(VLOOKUP(A10,data!A:V,22,FALSE),"") -> 8858890711061 | J10: =IFERROR(VLOOKUP(A10,'dataนน'!A:F,6,FALSE),"") -> 0.19 | K10: =IFERROR(VLOOKUP(A10,'dataนน'!A:G,7,FALSE),"") -> 180 กรัม | L10: 110 | M10: 120 | N10: 150 | O10: 10 | Q10: =IFERROR(VLOOKUP(A10,'data-ค่าฝา'!B:G,6,FALSE),"")
A11: BB-512 | B11: Barber Brain (บาร์เบอร์ เบรน) | C11: =IFERROR(VLOOKUP(A11,data!A:G,7,FALSE),"") -> Grooming - ผลิตภัณพ์จัดแต่งทรงผมและหนวด | D11: =IFERROR(VLOOKUP(A11,data!A:D,4,FALSE),"") -> ผลิตภัณฑ์สำหรับโกนหนวด บาร์เบอร์ เบรน ซิลเวอร์ เบลด เชฟวิ่ง ครีม BB-512 | G11: =IFERROR(VLOOKUP(A11,data!A:V,22,FALSE),"") -> 8858890732509 | J11: =IFERROR(VLOOKUP(A11,'dataนน'!A:F,6,FALSE),"") | K11: =IFERROR(VLOOKUP(A11,'dataนน'!A:G,7,FALSE),"") | L11: 170 | M11: 185 | N11: 250 | O11: 10 | Q11: =IFERROR(VLOOKUP(A11,'data-ค่าฝา'!B:G,6,FALSE),"")
A12: BB-513 | B12: Barber Brain (บาร์เบอร์ เบรน) | C12: =IFERROR(VLOOKUP(A12,data!A:G,7,FALSE),"") -> Grooming - ผลิตภัณพ์จัดแต่งทรงผมและหนวด | D12: =IFERROR(VLOOKUP(A12,data!A:D,4,FALSE),"") -> BB-513 after shave | G12: =IFERROR(VLOOKUP(A12,data!A:V,22,FALSE),"") -> 8858890732516 | J12: =IFERROR(VLOOKUP(A12,'dataนน'!A:F,6,FALSE),"") | K12: =IFERROR(VLOOKUP(A12,'dataนน'!A:G,7,FALSE),"") | L12: 140 | M12: 155 | N12: 190 | O12: 10 | Q12: =IFERROR(VLOOKUP(A12,'data-ค่าฝา'!B:G,6,FALSE),"")
A13: BB-703 | B13: Barber Brain (บาร์เบอร์ เบรน) | C13: =IFERROR(VLOOKUP(A13,data!A:G,7,FALSE),"") -> Chemical - เคมีภัณฑ์ | D13: =IFERROR(VLOOKUP(A13,data!A:D,4,FALSE),"") -> ชุดเจลน้ำยาดัดเย็น BB-703 และผง Down Perm BB-704 | G13: =IFERROR(VLOOKUP(A13,data!A:V,22,FALSE),"") -> 8858890712495 | J13: =IFERROR(VLOOKUP(A13,'dataนน'!A:F,6,FALSE),"") | K13: =IFERROR(VLOOKUP(A13,'dataนน'!A:G,7,FALSE),"") | L13: 125 | M13: 140 | N13: 250 | O13: 10 | Q13: =IFERROR(VLOOKUP(A13,'data-ค่าฝา'!B:G,6,FALSE),"") -> 10
A14: BB-704 | B14: Barber Brain (บาร์เบอร์ เบรน) | C14: =IFERROR(VLOOKUP(A14,data!A:G,7,FALSE),"") -> Chemical - เคมีภัณฑ์ | D14: =IFERROR(VLOOKUP(A14,data!A:D,4,FALSE),"") -> ผงผสมน้ำยาดัดเย็น Down Perm Powder BB-704 | G14: =IFERROR(VLOOKUP(A14,data!A:V,22,FALSE),"") -> 8858890732523 | J14: =IFERROR(VLOOKUP(A14,'dataนน'!A:F,6,FALSE),"") | K14: =IFERROR(VLOOKUP(A14,'dataนน'!A:G,7,FALSE),"") | L14: 25 | M14: 30 | N14: 50 | O14: 10 | Q14: =IFERROR(VLOOKUP(A14,'data-ค่าฝา'!B:G,6,FALSE),"")
A15: BB-514 | B15: Barber Brain (บาร์เบอร์ เบรน) | C15: =IFERROR(VLOOKUP(A15,data!A:G,7,FALSE),"") -> Grooming - ผลิตภัณพ์จัดแต่งทรงผมและหนวด | D15: =IFERROR(VLOOKUP(A15,data!A:D,4,FALSE),"") -> BB-514 บาร์เบอร์เบรน มูส กรูมมิ่ง ทอนนิค 100ml | G15: =IFERROR(VLOOKUP(A15,data!A:V,22,FALSE),"") -> 8858890798499 | J15: =IFERROR(VLOOKUP(A15,'dataนน'!A:F,6,FALSE),"") | K15: =IFERROR(VLOOKUP(A15,'dataนน'!A:G,7,FALSE),"") | L15: 120 | M15: 130 | N15: 240 | O15: 10 | Q15: =IFERROR(VLOOKUP(A15,'data-ค่าฝา'!B:G,6,FALSE),"")
A16: BB-515 | B16: Barber Brain (บาร์เบอร์ เบรน) | C16: =IFERROR(VLOOKUP(A16,data!A:G,7,FALSE),"") -> Grooming - ผลิตภัณพ์จัดแต่งทรงผมและหนวด | D16: =IFERROR(VLOOKUP(A16,data!A:D,4,FALSE),"") -> BB-515 pre shave | G16: =IFERROR(VLOOKUP(A16,data!A:V,22,FALSE),"") -> 8858890798666 | J16: =IFERROR(VLOOKUP(A16,'dataนน'!A:F,6,FALSE),"") | K16: =IFERROR(VLOOKUP(A16,'dataนน'!A:G,7,FALSE),"") | L16: 170 | M16: 185 | N16: 250 | O16: 10 | Q16: =IFERROR(VLOOKUP(A16,'data-ค่าฝา'!B:G,6,FALSE),"")
A17: BB-111 | B17: Barber Brain (บาร์เบอร์ เบรน) | C17: =IFERROR(VLOOKUP(A17,data!A:G,7,FALSE),"") -> Electrical Equipment - อุปกรณ์ไฟฟ้า | D17: =IFERROR(VLOOKUP(A17,data!A:D,4,FALSE),"") -> ปัตตาเลี่ยนไร้สาย Barber Brain รุ่น Stella BB-111 | E17: ปัตตาเลี่ยนขึ้นทรง,ปัตตาเลี่ยนเฟด(Fade),ไร้สาย | F17: 12 | G17: =IFERROR(VLOOKUP(A17,data!A:V,22,FALSE),"") -> 8858890799557 | J17: =IFERROR(VLOOKUP(A17,'dataนน'!A:F,6,FALSE),"") | K17: =IFERROR(VLOOKUP(A17,'dataนน'!A:G,7,FALSE),"") | L17: 1350 | M17: 1485 | N17: 1950 | O17: 10 | Q17: =IFERROR(VLOOKUP(A17,'data-ค่าฝา'!B:G,6,FALSE),"") -> 80
A18: BB-112 | B18: Barber Brain (บาร์เบอร์ เบรน) | C18: =IFERROR(VLOOKUP(A18,data!A:G,7,FALSE),"") -> Electrical Equipment - อุปกรณ์ไฟฟ้า | D18: =IFERROR(VLOOKUP(A18,data!A:D,4,FALSE),"") -> Barber Brain Trimmer ปัตตาเลี่ยนกันขอบไร้สาย รุ่น Stella BB-112 | F18: 12 | G18: =IFERROR(VLOOKUP(A18,data!A:V,22,FALSE),"") -> 8858890799786 | J18: =IFERROR(VLOOKUP(A18,'dataนน'!A:F,6,FALSE),"") | K18: =IFERROR(VLOOKUP(A18,'dataนน'!A:G,7,FALSE),"") | L18: 1000 | M18: 1100 | N18: 1350 | O18: 10 | Q18: =IFERROR(VLOOKUP(A18,'data-ค่าฝา'!B:G,6,FALSE),"") -> 80
A19: BB-108 | B19: Barber Brain (บาร์เบอร์ เบรน) | C19: =IFERROR(VLOOKUP(A19,data!A:G,7,FALSE),"") -> Electrical Equipment - อุปกรณ์ไฟฟ้า | D19: =IFERROR(VLOOKUP(A19,data!A:D,4,FALSE),"") -> ปัตตาเลี่ยนไร้สาย BB-108 แถมหวีรองซอย BB-106-06 | E19: ปัตตาเลี่ยนเฟด(Fade),ไร้สาย | F19: 20 | G19: =IFERROR(VLOOKUP(A19,data!A:V,22,FALSE),"") -> 8588890721172 | J19: =IFERROR(VLOOKUP(A19,'dataนน'!A:F,6,FALSE),"") -> 0.05 | K19: =IFERROR(VLOOKUP(A19,'dataนน'!A:G,7,FALSE),"") | L19: 1050 | M19: 1155 | N19: 1450 | O19: 10 | Q19: =IFERROR(VLOOKUP(A19,'data-ค่าฝา'!B:G,6,FALSE),"") -> 50
A20: BB-110 | B20: Barber Brain (บาร์เบอร์ เบรน) | C20: =IFERROR(VLOOKUP(A20,data!A:G,7,FALSE),"") -> Electrical Equipment - อุปกรณ์ไฟฟ้า | D20: =IFERROR(VLOOKUP(A20,data!A:D,4,FALSE),"") -> ปัตตาเลี่ยน BB-110 แถมหวี BB-106-06 และรองฟัน BB-103 | E20: ปัตตาเลี่ยนขึ้นทรง,ไร้สาย | F20: 20 | G20: =IFERROR(VLOOKUP(A20,data!A:V,22,FALSE),"") -> 8858890721220 | J20: =IFERROR(VLOOKUP(A20,'dataนน'!A:F,6,FALSE),"") -> 0.85 | K20: =IFERROR(VLOOKUP(A20,'dataนน'!A:G,7,FALSE),"") | L20: 1050 | M20: 1155 | N20: 1500 | O20: 10 | Q20: =IFERROR(VLOOKUP(A20,'data-ค่าฝา'!B:G,6,FALSE),"") -> 50
A21: BB-100 | B21: Barber Brain (บาร์เบอร์ เบรน) | C21: =IFERROR(VLOOKUP(A21,data!A:G,7,FALSE),"") -> Electrical Equipment - อุปกรณ์ไฟฟ้า | D21: =IFERROR(VLOOKUP(A21,data!A:D,4,FALSE),"") -> บาร์เบอร์เบรนปัตตาเลี่ยน T-Blade ไร้สาย BB-100 | F21: 24 | G21: =IFERROR(VLOOKUP(A21,data!A:V,22,FALSE),"") -> 8858890721077 | J21: =IFERROR(VLOOKUP(A21,'dataนน'!A:F,6,FALSE),"") -> 0.05 | K21: =IFERROR(VLOOKUP(A21,'dataนน'!A:G,7,FALSE),"") | L21: 420 | M21: 460 | N21: 750 | O21: 10 | P21: 65 | Q21: =IFERROR(VLOOKUP(A21,'data-ค่าฝา'!B:G,6,FALSE),"") -> 20
A22: BB-103 | B22: Barber Brain (บาร์เบอร์ เบรน) | C22: =IFERROR(VLOOKUP(A22,data!A:G,7,FALSE),"") -> Electrical Equipment - อุปกรณ์ไฟฟ้า | D22: =IFERROR(VLOOKUP(A22,data!A:D,4,FALSE),"") -> รองฟัน BB-103 | G22: =IFERROR(VLOOKUP(A22,data!A:V,22,FALSE),"") -> 8858890796501 | J22: =IFERROR(VLOOKUP(A22,'dataนน'!A:F,6,FALSE),"") -> 0.05 | K22: =IFERROR(VLOOKUP(A22,'dataนน'!A:G,7,FALSE),"") -> เบอร์ 0.5 หนา 5 , 1.5 หนา 4.6 | L22: 75 | M22: 85 | N22: 200 | O22: 10 | Q22: =IFERROR(VLOOKUP(A22,'data-ค่าฝา'!B:G,6,FALSE),"")
A23: BB-103/A | B23: Barber Brain (บาร์เบอร์ เบรน) | C23: =IFERROR(VLOOKUP(A23,data!A:G,7,FALSE),"") | D23: =IFERROR(VLOOKUP(A23,data!A:D,4,FALSE),"") | G23: =IFERROR(VLOOKUP(A23,data!A:V,22,FALSE),"") | J23: =IFERROR(VLOOKUP(A23,'dataนน'!A:F,6,FALSE),"") | K23: =IFERROR(VLOOKUP(A23,'dataนน'!A:G,7,FALSE),"") | L23: 38 | M23: 40 | N23: 150 | O23: 10 | Q23: =IFERROR(VLOOKUP(A23,'data-ค่าฝา'!B:G,6,FALSE),"")
A24: BB-104 | B24: Barber Brain (บาร์เบอร์ เบรน) | C24: =IFERROR(VLOOKUP(A24,data!A:G,7,FALSE),"") -> Electrical Equipment - อุปกรณ์ไฟฟ้า | D24: =IFERROR(VLOOKUP(A24,data!A:D,4,FALSE),"") -> BARBER BRAIN รองฟันปัตตาเลี่ยน ชนิดแม่เหล็ก รุ่น BB-104 | G24: =IFERROR(VLOOKUP(A24,data!A:V,22,FALSE),"") -> 8858890793364 | J24: =IFERROR(VLOOKUP(A24,'dataนน'!A:F,6,FALSE),"") -> 0.05 | K24: =IFERROR(VLOOKUP(A24,'dataนน'!A:G,7,FALSE),"") -> เบอร์ 0-4 ขนาด 1.5-13 mm. | L24: 140 | M24: 155 | N24: 250 | O24: 10 | Q24: =IFERROR(VLOOKUP(A24,'data-ค่าฝา'!B:G,6,FALSE),"")
A25: ZM-BB-111/4 | B25: Barber Brain (บาร์เบอร์ เบรน) | C25: =IFERROR(VLOOKUP(A25,data!A:G,7,FALSE),"") -> Replacement Parts - ชิ้นส่วนอะไหล่ | D25: =IFERROR(VLOOKUP(A25,data!A:D,4,FALSE),"") -> ชุดฟันปัตตาเลี่ยน Stella | G25: =IFERROR(VLOOKUP(A25,data!A:V,22,FALSE),"") -> 8858890799601 | J25: =IFERROR(VLOOKUP(A25,'dataนน'!A:F,6,FALSE),"") | K25: =IFERROR(VLOOKUP(A25,'dataนน'!A:G,7,FALSE),"") | L25: 210 | M25: 230 | N25: 300 | O25: 10 | Q25: =IFERROR(VLOOKUP(A25,'data-ค่าฝา'!B:G,6,FALSE),"")
A26: VAL-64 | B26: Barber Brain (บาร์เบอร์ เบรน) | C26: =IFERROR(VLOOKUP(A26,data!A:G,7,FALSE),"") -> Hair Scissors - กรรไกรตัดซอย | D26: Barber Brain Black Beast Barber Scissors 6.5" | E26: 6.5" | G26: =IFERROR(VLOOKUP(A26,data!A:V,22,FALSE),"") -> 8858890761042 | J26: =IFERROR(VLOOKUP(A26,'dataนน'!A:F,6,FALSE),"") -> 0.145 | K26: =IFERROR(VLOOKUP(A26,'dataนน'!A:G,7,FALSE),"") -> 6.5 นิ้ว | L26: 315 | M26: 345 | N26: 450 | O26: 10 | Q26: =IFERROR(VLOOKUP(A26,'data-ค่าฝา'!B:G,6,FALSE),"")
A27: VAL-65 | B27: Barber Brain (บาร์เบอร์ เบรน) | C27: =IFERROR(VLOOKUP(A27,data!A:G,7,FALSE),"") -> Hair Scissors - กรรไกรตัดซอย | D27: Barber Brain Black Beast Thinning Scissor 6" | E27: 6" | G27: =IFERROR(VLOOKUP(A27,data!A:V,22,FALSE),"") -> 8858890761059 | J27: =IFERROR(VLOOKUP(A27,'dataนน'!A:F,6,FALSE),"") -> 0.145 | K27: =IFERROR(VLOOKUP(A27,'dataนน'!A:G,7,FALSE),"") -> 6.5 นิ้ว | L27: 325 | M27: 360 | N27: 450 | O27: 10 | Q27: =IFERROR(VLOOKUP(A27,'data-ค่าฝา'!B:G,6,FALSE),"")
A28: VAL-66 | B28: Barber Brain (บาร์เบอร์ เบรน) | C28: =IFERROR(VLOOKUP(A28,data!A:G,7,FALSE),"") -> Hair Scissors - กรรไกรตัดซอย | D28: =IFERROR(VLOOKUP(A28,data!A:D,4,FALSE),"") -> BARBER SCISSORS กรรไกรตัดมือซ้าย 6.5 | E28: 6.5" | G28: =IFERROR(VLOOKUP(A28,data!A:V,22,FALSE),"") -> 8858890761066 | J28: =IFERROR(VLOOKUP(A28,'dataนน'!A:F,6,FALSE),"") -> 0.14 | K28: =IFERROR(VLOOKUP(A28,'dataนน'!A:G,7,FALSE),"") -> 6 นิ้ว | L28: 320 | M28: 350 | N28: 450 | O28: 10 | Q28: =IFERROR(VLOOKUP(A28,'data-ค่าฝา'!B:G,6,FALSE),"")
A29: VAL-67 | B29: Barber Brain (บาร์เบอร์ เบรน) | C29: =IFERROR(VLOOKUP(A29,data!A:G,7,FALSE),"") -> Hair Scissors - กรรไกรตัดซอย | D29: =IFERROR(VLOOKUP(A29,data!A:D,4,FALSE),"") -> BARBER SCISSORS กรรไกรซอยมือซ้าย 6 | E29: 6" | G29: =IFERROR(VLOOKUP(A29,data!A:V,22,FALSE),"") -> 8858890761073 | J29: =IFERROR(VLOOKUP(A29,'dataนน'!A:F,6,FALSE),"") -> 0.135 | K29: =IFERROR(VLOOKUP(A29,'dataนน'!A:G,7,FALSE),"") -> 6 นิ้ว | L29: 320 | M29: 350 | N29: 450 | O29: 10 | Q29: =IFERROR(VLOOKUP(A29,'data-ค่าฝา'!B:G,6,FALSE),"")
A30: VAL-73 | B30: Barber Brain (บาร์เบอร์ เบรน) | C30: =IFERROR(VLOOKUP(A30,data!A:G,7,FALSE),"") -> Hair Scissors - กรรไกรตัดซอย | D30: =IFERROR(VLOOKUP(A30,data!A:D,4,FALSE),"") -> กรรไกรตัดผม 6.5 | E30: 6.5" | G30: =IFERROR(VLOOKUP(A30,data!A:V,22,FALSE),"") -> 8858890799823 | J30: =IFERROR(VLOOKUP(A30,'dataนน'!A:F,6,FALSE),"") | K30: =IFERROR(VLOOKUP(A30,'dataนน'!A:G,7,FALSE),"") | L30: 315 | M30: 345 | N30: 450 | O30: 10 | Q30: =IFERROR(VLOOKUP(A30,'data-ค่าฝา'!B:G,6,FALSE),"")
A31: VAL-74 | B31: Barber Brain (บาร์เบอร์ เบรน) | C31: =IFERROR(VLOOKUP(A31,data!A:G,7,FALSE),"") -> Hair Scissors - กรรไกรตัดซอย | D31: =IFERROR(VLOOKUP(A31,data!A:D,4,FALSE),"") -> กรรไกรฟันปลา 6 | E31: 6" | G31: =IFERROR(VLOOKUP(A31,data!A:V,22,FALSE),"") -> 8858890799830 | J31: =IFERROR(VLOOKUP(A31,'dataนน'!A:F,6,FALSE),"") | K31: =IFERROR(VLOOKUP(A31,'dataนน'!A:G,7,FALSE),"") | L31: 325 | M31: 360 | N31: 450 | O31: 10 | Q31: =IFERROR(VLOOKUP(A31,'data-ค่าฝา'!B:G,6,FALSE),"")
A32: ZP-A16015 | B32: Barber Brain (บาร์เบอร์ เบรน) | C32: =IFERROR(VLOOKUP(A32,data!A:G,7,FALSE),"") -> Apron - ผ้าคลุมและผ้ากันเปื้อน | D32: =IFERROR(VLOOKUP(A32,data!A:D,4,FALSE),"") -> บาร์เบอร์ เบรน เอี๊ยมช่างบาร์เบอร์ ผูกหลัง 0.401g. รหัสสินค้า ZP-A16015 | E32: 70x80cm | G32: =IFERROR(VLOOKUP(A32,data!A:V,22,FALSE),"") -> 8858890794804 | J32: =IFERROR(VLOOKUP(A32,'dataนน'!A:F,6,FALSE),"") -> 0.05 | K32: =IFERROR(VLOOKUP(A32,'dataนน'!A:G,7,FALSE),"") -> กว้าง 69 ซม. สูง 80 ซม. | L32: 400 | M32: 425 | N32: 435 | O32: 10 | Q32: =IFERROR(VLOOKUP(A32,'data-ค่าฝา'!B:G,6,FALSE),"")
A33: VAL-1516 | B33: Barber Brain (บาร์เบอร์ เบรน) | C33: =IFERROR(VLOOKUP(A33,data!A:G,7,FALSE),"") -> Apron - ผ้าคลุมและผ้ากันเปื้อน | D33: =IFERROR(VLOOKUP(A33,data!A:D,4,FALSE),"") -> ผ้าคลุม Stella VAL-1516 | E33: กันน้ำ 80% 145x160cm | G33: =IFERROR(VLOOKUP(A33,data!A:V,22,FALSE),"") -> 8858890799939 | J33: =IFERROR(VLOOKUP(A33,'dataนน'!A:F,6,FALSE),"") | K33: =IFERROR(VLOOKUP(A33,'dataนน'!A:G,7,FALSE),"") | L33: 150 | M33: 165 | N33: 190 | O33: 10 | Q33: =IFERROR(VLOOKUP(A33,'data-ค่าฝา'!B:G,6,FALSE),"")
A34: VAL-K099 | B34: Barber Brain (บาร์เบอร์ เบรน) | C34: =IFERROR(VLOOKUP(A34,data!A:G,7,FALSE),"") -> Apron - ผ้าคลุมและผ้ากันเปื้อน | D34: =IFERROR(VLOOKUP(A34,data!A:D,4,FALSE),"") -> BARBER BRAIN ผ้าคลุมซอยลายทหาร รุ่น VAL-K099 | E34: 135x150cm | G34: =IFERROR(VLOOKUP(A34,data!A:V,22,FALSE),"") -> 8858890796488 | J34: =IFERROR(VLOOKUP(A34,'dataนน'!A:F,6,FALSE),"") -> 0.05 | K34: =IFERROR(VLOOKUP(A34,'dataนน'!A:G,7,FALSE),"") -> กว้าง 118 ซม. สูง 145 ซม. | L34: 135 | M34: 150 | N34: 200 | O34: 10 | Q34: =IFERROR(VLOOKUP(A34,'data-ค่าฝา'!B:G,6,FALSE),"")
A35: VAL-K024 | B35: Barber Brain (บาร์เบอร์ เบรน) | C35: =IFERROR(VLOOKUP(A35,data!A:G,7,FALSE),"") -> Apron - ผ้าคลุมและผ้ากันเปื้อน | D35: =IFERROR(VLOOKUP(A35,data!A:D,4,FALSE),"") -> ผ้าคลุมซอยบาร์เบอร์ มีแขน บาร์เบอร์เบรนสีดำ 0.211g. รหัสสินค้า VAL-K024 | E35: 120x160cm | G35: =IFERROR(VLOOKUP(A35,data!A:V,22,FALSE),"") -> 8858890726041 | J35: =IFERROR(VLOOKUP(A35,'dataนน'!A:F,6,FALSE),"") -> 0.05 | K35: =IFERROR(VLOOKUP(A35,'dataนน'!A:G,7,FALSE),"") -> 164x123 ซม. | L35: 200 | M35: 220 | N35: 250 | O35: 10 | Q35: =IFERROR(VLOOKUP(A35,'data-ค่าฝา'!B:G,6,FALSE),"")
A36: VAL-1513 | B36: Barber Brain (บาร์เบอร์ เบรน) | C36: =IFERROR(VLOOKUP(A36,data!A:G,7,FALSE),"") -> Apron - ผ้าคลุมและผ้ากันเปื้อน | D36: =IFERROR(VLOOKUP(A36,data!A:D,4,FALSE),"") -> BARBER BRAIN CUTTING PINK APRON : ผ้าคลุมซอย บาร์เบอร์เบรน สีชมพู VAL-1513 | E36: 140x150cm | G36: =IFERROR(VLOOKUP(A36,data!A:V,22,FALSE),"") -> 88588907958522 | J36: =IFERROR(VLOOKUP(A36,'dataนน'!A:F,6,FALSE),"") -> 0.55 | K36: =IFERROR(VLOOKUP(A36,'dataนน'!A:G,7,FALSE),"") -> กว้าง 140 ซม. สูง 150 ซม. | L36: 150 | M36: 165 | N36: 190 | O36: 10 | Q36: =IFERROR(VLOOKUP(A36,'data-ค่าฝา'!B:G,6,FALSE),"")
A37: VAL-1510/W-1 | B37: Barber Brain (บาร์เบอร์ เบรน) | C37: =IFERROR(VLOOKUP(A37,data!A:G,7,FALSE),"") -> Apron - ผ้าคลุมและผ้ากันเปื้อน | D37: =IFERROR(VLOOKUP(A37,data!A:D,4,FALSE),"") -> Barber Brain ผ้าคลุมซอย VAL-1510/W-1 | E37: 120x140cm | G37: =IFERROR(VLOOKUP(A37,data!A:V,22,FALSE),"") -> 8858890795900 | J37: =IFERROR(VLOOKUP(A37,'dataนน'!A:F,6,FALSE),"") -> 0.55 | K37: =IFERROR(VLOOKUP(A37,'dataนน'!A:G,7,FALSE),"") -> 153x123 ซม. | L37: 84 | M37: 90 | N37: 120 | O37: 10 | Q37: =IFERROR(VLOOKUP(A37,'data-ค่าฝา'!B:G,6,FALSE),"")
A38: VAL-1510/W | B38: Barber Brain (บาร์เบอร์ เบรน) | C38: =IFERROR(VLOOKUP(A38,data!A:G,7,FALSE),"") -> Apron - ผ้าคลุมและผ้ากันเปื้อน | D38: =IFERROR(VLOOKUP(A38,data!A:D,4,FALSE),"") -> ผ้าคลุมซอย สกรีนโลโก้ Barber Brain สีขาว VAL-1510/W | E38: 120x140cm | G38: =IFERROR(VLOOKUP(A38,data!A:V,22,FALSE),"") -> 8858890794583 | J38: =IFERROR(VLOOKUP(A38,'dataนน'!A:F,6,FALSE),"") -> 0.55 | K38: =IFERROR(VLOOKUP(A38,'dataนน'!A:G,7,FALSE),"") | L38: 87.08 | M38: 95 | N38: 120 | O38: 10 | Q38: =IFERROR(VLOOKUP(A38,'data-ค่าฝา'!B:G,6,FALSE),"")
A39: VAL-1510/B-1 | B39: Barber Brain (บาร์เบอร์ เบรน) | C39: =IFERROR(VLOOKUP(A39,data!A:G,7,FALSE),"") -> Apron - ผ้าคลุมและผ้ากันเปื้อน | D39: =IFERROR(VLOOKUP(A39,data!A:D,4,FALSE),"") -> Barber Brain ผ้าคลุมซอย Barber Brain ผ้าคลุมซอย VAL-1510/B-1 | E39: 120x140cm | G39: =IFERROR(VLOOKUP(A39,data!A:V,22,FALSE),"") -> 8858890795917 | J39: =IFERROR(VLOOKUP(A39,'dataนน'!A:F,6,FALSE),"") -> 0.55 | K39: =IFERROR(VLOOKUP(A39,'dataนน'!A:G,7,FALSE),"") -> กว้าง 122 ซม. สูง 143 ซม. | L39: 84 | M39: 90 | N39: 120 | O39: 10 | Q39: =IFERROR(VLOOKUP(A39,'data-ค่าฝา'!B:G,6,FALSE),"")
... A42: VAL-1511/B | B42: Barber Brain (บาร์เบอร์ เบรน) | C42: =IFERROR(VLOOKUP(A42,data!A:G,7,FALSE),"") -> Apron - ผ้าคลุมและผ้ากันเปื้อน | D42: =IFERROR(VLOOKUP(A42,data!A:D,4,FALSE),"") -> ผ้าคลุมซอย บาร์เบอร์เบรน VAL-1511/B | E42: 135x150cm | G42: =IFERROR(VLOOKUP(A42,data!A:V,22,FALSE),"") -> 8858890795740 | J42: =IFERROR(VLOOKUP(A42,'dataนน'!A:F,6,FALSE),"") -> 0.55 | K42: =IFERROR(VLOOKUP(A42,'dataนน'!A:G,7,FALSE),"") -> กว้าง 135 ซม. สูง 150 ซม. | L42: 154 | M42: 170 | N42: 195 | O42: 10 | Q42: =IFERROR(VLOOKUP(A42,'data-ค่าฝา'!B:G,6,FALSE),"")
...

Sheet recheck
A1: ลำดับ | B1: รหัส | C1: ราคาออนไลน์ | D1: Checklist Platform เปิดสินค้า
D2: Com merzy | E2: Shopee : Valente | F2: Shopee : BB | G2: Lazada : CMS | H2: Lazada : Valente | I2: Lazada : L'Angel | J2: Tiktok : CMS | K2: Tiktok : BB
A3: {=if(B3:B990<>"",ROW(B3:B990)-2,"")} -> 1 | B3: BB-201 | C3: 350 | D3: FALSE | E3: FALSE | F3: FALSE | G3: FALSE | H3: FALSE | J3: FALSE | K3: FALSE
A4: 2 | B4: BB-202 | C4: 350 | D4: FALSE | E4: FALSE | F4: FALSE | G4: FALSE | H4: FALSE | J4: FALSE | K4: FALSE
A5: 3 | B5: BB-203 | C5: 350 | D5: FALSE | E5: FALSE | F5: FALSE | G5: FALSE | H5: FALSE | J5: FALSE | K5: FALSE
A6: 4 | B6: BB-204 | C6: 385 | D6: FALSE | E6: FALSE | F6: FALSE | G6: FALSE | H6: FALSE | J6: FALSE | K6: FALSE
A7: 5 | B7: BB-205 | C7: 385 | D7: FALSE | E7: FALSE | F7: FALSE | G7: FALSE | H7: FALSE | J7: FALSE | K7: FALSE
A8: 6 | B8: BB-206 | C8: 385 | D8: FALSE | E8: FALSE | F8: FALSE | G8: FALSE | H8: FALSE | J8: FALSE | K8: FALSE
A9: 7 | B9: ZM-BB-111-4 | C9: 300 | D9: FALSE | E9: FALSE | F9: FALSE | G9: FALSE | H9: FALSE | J9: FALSE | K9: FALSE
A10: 8 | B10: VAL-1517 | C10: 220 | D10: FALSE | E10: FALSE | F10: FALSE | G10: FALSE | H10: FALSE | J10: FALSE | K10: FALSE
A11: 9 | B11: H-004 | C11: 950 | D11: FALSE | E11: FALSE | F11: FALSE | G11: FALSE | H11: FALSE | J11: FALSE | K11: FALSE
A12: 10 | B12: H-005 | C12: 1950 | D12: FALSE | E12: FALSE | F12: FALSE | G12: FALSE | H12: FALSE | J12: FALSE | K12: FALSE
A13: 11 | B13: H-010 | C13: 325 | D13: FALSE | E13: FALSE | F13: FALSE | G13: FALSE | H13: FALSE | J13: FALSE | K13: FALSE
A14: 12 | B14: H-011 | C14: 635 | D14: FALSE | E14: FALSE | F14: FALSE | G14: FALSE | H14: FALSE | J14: FALSE | K14: FALSE
A15: 13 | B15: VAL-700 | C15: 200 | D15: FALSE | E15: FALSE | F15: FALSE | G15: FALSE | H15: FALSE | I15: FALSE | J15: FALSE | K15: FALSE
A16: 14 | B16: VAL-800 | C16: 200 | D16: FALSE | E16: FALSE | F16: FALSE | G16: FALSE | H16: FALSE | I16: FALSE | J16: FALSE | K16: FALSE
A17: 15 | B17: VAL-651 | C17: 40 | D17: FALSE | E17: FALSE | G17: FALSE | H17: FALSE | I17: FALSE | J17: FALSE
A18: 16 | B18: VAL-651/1 | C18: 65 | D18: FALSE | E18: FALSE | G18: FALSE | H18: FALSE | I18: FALSE | J18: FALSE
A19: 17 | B19: VAL-025-1 | C19: 200 | D19: FALSE | E19: FALSE | G19: FALSE | H19: FALSE | I19: FALSE | J19: FALSE
A20: 18 | B20: VAL-025-2 | C20: 215 | D20: FALSE | E20: FALSE | G20: FALSE | H20: FALSE | I20: FALSE | J20: FALSE
A21: 19 | B21: VAL-025-3 | C21: 230 | D21: FALSE | E21: FALSE | G21: FALSE | H21: FALSE | I21: FALSE | J21: FALSE
A22: 20 | B22: VAL-025-4 | C22: 240 | D22: FALSE | E22: FALSE | G22: FALSE | H22: FALSE | I22: FALSE | J22: FALSE
A23: 21 | B23: VAL-300 | C23: 100 | D23: FALSE | E23: FALSE | G23: FALSE | H23: FALSE | I23: FALSE | J23: FALSE
A24: 22 | B24: Q-71 | C24: 120 | D24: FALSE | E24: FALSE | G24: FALSE | H24: FALSE | I24: FALSE | J24: FALSE
A25: 23 | B25: A-041 | C25: 125 | D25: FALSE | E25: FALSE | G25: FALSE | H25: FALSE | J25: FALSE
A26: 24 | B26: BB-518/BL | C26: 150 | D26: FALSE | E26: FALSE | F26: FALSE | G26: FALSE | J26: FALSE | K26: FALSE
A27: 25 | B27: BB-518/DB | C27: 150 | D27: FALSE | E27: FALSE | F27: FALSE | G27: FALSE | J27: FALSE | K27: FALSE
A28: 26 | B28: AC-BB-518/AP | C28: 150 | D28: FALSE | E28: FALSE | F28: FALSE | G28: FALSE | J28: FALSE | K28: FALSE
A29: 27 | B29: BB-518/BL-R | C29: 150 | D29: FALSE | E29: FALSE | F29: FALSE | G29: FALSE | J29: FALSE | K29: FALSE
A30: 28 | B30: BB-518/DB-R | C30: 150 | D30: FALSE | E30: FALSE | F30: FALSE | G30: FALSE | J30: FALSE | K30: FALSE
A31: 29 | B31: BB-519/BL | C31: 150 | D31: FALSE | E31: FALSE | F31: FALSE | G31: FALSE | J31: FALSE | K31: FALSE
A32: 30 | B32: BB-519/BR | C32: 150 | D32: FALSE | E32: FALSE | F32: FALSE | G32: FALSE | J32: FALSE | K32: FALSE
A33: 31 | B33: BB-517/1 | C33: 150 | D33: FALSE | E33: FALSE | F33: FALSE | G33: FALSE | J33: FALSE | K33: FALSE
A34: 32 | B34: ANG-412 | C34: 185 | D34: FALSE | E34: FALSE | G34: FALSE | I34: FALSE | J34: FALSE
A35: 33 | B35: VAL-XE2-8 | C35: 50 | D35: FALSE | E35: FALSE | F35: FALSE | G35: FALSE | H35: FALSE | J35: FALSE | K35: FALSE

Sheet สินค้าL
C1: ระดับราคา | E1: 20%-50%
A2: รหัสสินค้า | B2: ราคาส่ง | C2: ราคา+10% | D2: ราคา+15% | E2: ราคาปลีกออนไลน์
A3: Angelic | B3: 55 | C3: =MROUND((B3*10%)+B3,5) -> 60 | D3: =MROUND((B3*15%)+B3,5) -> 65 | E3: 75 | F3: =(E3-B3)/B3 -> 0.36363636 | G3: =E3-C3 -> 15 | H3: =E3-D3 -> 10
A4: icolor | B4: 75 | C4: 80 | D4: =MROUND((B4*15%)+B4,5) -> 85 | E4: 80 | F4: =(E4-B4)/B4 -> 0.066666667 | G4: =E4-C4 -> 0 | H4: =E4-D4 -> -5
A5: infinity | B5: 65 | C5: =MROUND((B5*10%)+B5,5) -> 70 | D5: =MROUND((B5*15%)+B5,5) -> 75 | E5: 90 | F5: =(E5-B5)/B5 -> 0.38461538 | G5: =E5-C5 -> 20 | H5: =E5-D5 -> 15
A6: ANG-066 | B6: 250 | C6: =MROUND((B6*10%)+B6,5) -> 275 | D6: =MROUND((B6*15%)+B6,5) -> 290 | E6: 365 | F6: =(E6-B6)/B6 -> 0.46 | G6: =E6-C6 -> 90 | H6: =E6-D6 -> 75
A7: ANG-069 | B7: 200 | C7: =MROUND((B7*10%)+B7,5) -> 220 | D7: =MROUND((B7*15%)+B7,5) -> 230 | E7: 390 | F7: =(E7-B7)/B7 -> 0.95 | G7: =E7-C7 -> 170 | H7: =E7-D7 -> 160
A8: ANG-110 | B8: 320 | C8: =MROUND((B8*10%)+B8,5) -> 350 | D8: =MROUND((B8*15%)+B8,5) -> 370 | E8: 150 | F8: =(E8-B8)/B8 -> -0.53125 | G8: =E8-C8 -> -200 | H8: =E8-D8 -> -220
A9: ANG-109 | B9: 320 | C9: =MROUND((B9*10%)+B9,5) -> 350 | D9: =MROUND((B9*15%)+B9,5) -> 370 | E9: 150 | F9: =(E9-B9)/B9 -> -0.53125 | G9: =E9-C9 -> -200 | H9: =E9-D9 -> -220
A10: ANG-613 | B10: 650 | C10: =MROUND((B10*10%)+B10,5) -> 715 | D10: =MROUND((B10*15%)+B10,5) -> 750 | E10: 800 | F10: =(E10-B10)/B10 -> 0.23076923 | G10: =E10-C10 -> 85 | H10: =E10-D10 -> 50
A11: ANG-608 | B11: 320 | C11: =MROUND((B11*10%)+B11,5) -> 350 | D11: =MROUND((B11*15%)+B11,5) -> 370 | E11: 399 | F11: =(E11-B11)/B11 -> 0.246875 | G11: =E11-C11 -> 49 | H11: =E11-D11 -> 29
A12: ANG-410 | B12: 1000 | C12: =MROUND((B12*10%)+B12,5) -> 1100 | D12: =MROUND((B12*15%)+B12,5) -> 1150 | E12: 1350 | F12: =(E12-B12)/B12 -> 0.35 | G12: =E12-C12 -> 250 | H12: =E12-D12 -> 200
A13: ANG-610 | B13: 190 | C13: =MROUND((B13*10%)+B13,5) -> 210 | D13: =MROUND((B13*15%)+B13,5) -> 220 | E13: 240 | F13: =(E13-B13)/B13 -> 0.26315789 | G13: =E13-C13 -> 30 | H13: =E13-D13 -> 20
A14: ANG-606 | B14: 160 | C14: =MROUND((B14*10%)+B14,5) -> 175 | D14: =MROUND((B14*15%)+B14,5) -> 185 | E14: 210 | F14: =(E14-B14)/B14 -> 0.3125 | G14: =E14-C14 -> 35 | H14: =E14-D14 -> 25
A15: ANG-209 | B15: 250 | C15: =MROUND((B15*10%)+B15,5) -> 275 | D15: =MROUND((B15*15%)+B15,5) -> 290 | E15: 320 | F15: =(E15-B15)/B15 -> 0.28 | G15: =E15-C15 -> 45 | H15: =E15-D15 -> 30
A16: ANG-303 | B16: 250 | C16: =MROUND((B16*10%)+B16,5) -> 275 | D16: =MROUND((B16*15%)+B16,5) -> 290 | E16: 499 | F16: =(E16-B16)/B16 -> 0.996 | G16: =E16-C16 -> 224 | H16: =E16-D16 -> 209
... A1002: PROD-005 | B1002: 240 | C1002: =MROUND((B1002*10%)+B1002,5) | D1002: =MROUND((B1002*15%)+B1002,5) | E1002: 350 | F1002: =(E1002-B1002)/B1002 | G1002: =E1002-C1002 | H1002: =E1002-D1002

Sheet สินค้าV
D1: ระดับราคา | F1: 20%-50%
A2: รหัสสินค้า | B2: ราคาส่ง | C2: ค่าลับคม | D2: ราคา+10% | E2: ราคา+15% | F2: ราคาปลีกออนไลน์
A3: HF-017 | B3: 1250 | D3: =CEILING(B3*1.1,5) -> 1375 | E3: =CEILING(B3*1.15,5) -> 1440 | F3: 1650 | G3: =(E3-B3)/B3 -> 0.152 | H3: =F3-E3 -> 210
A4: HF-013 | B4: 1250 | D4: =CEILING(B4*1.1,5) -> 1375 | E4: =CEILING(B4*1.15,5) -> 1440 | F4: 1750 | G4: =(E4-B4)/B4 -> 0.152 | H4: =F4-E4 -> 310
A5: HF-001 | B5: 580 | D5: =CEILING(B5*1.1,5) -> 640 | E5: =CEILING(B5*1.15,5) -> 670 | F5: 670 | G5: =(E5-B5)/B5 -> 0.15517241 | H5: =F5-E5 -> 0
A6: HF-002 | B6: 950 | D6: =CEILING(B6*1.1,5) -> 1045 | E6: =CEILING(B6*1.15,5) -> 1095 | F6: 1250 | G6: =(E6-B6)/B6 -> 0.15263158 | H6: =F6-E6 -> 155
A7: HC-003/28 | B7: 950 | D7: =CEILING(B7*1.1,5) -> 1045 | E7: =CEILING(B7*1.15,5) -> 1095 | F7: 1250 | G7: =(E7-B7)/B7 -> 0.15263158 | H7: =F7-E7 -> 155
A8: HC-003/38 | B8: 950 | D8: =CEILING(B8*1.1,5) -> 1045 | E8: =CEILING(B8*1.15,5) -> 1095 | F8: 1250 | G8: =(E8-B8)/B8 -> 0.15263158 | H8: =F8-E8 -> 155
A9: HC-002/25 | B9: 650 | D9: =CEILING(B9*1.1,5) -> 715 | E9: =CEILING(B9*1.15,5) -> 750 | F9: 1250 | G9: =(E9-B9)/B9 -> 0.15384615 | H9: =F9-E9 -> 500
A10: HC-002/32 | B10: 650 | D10: =CEILING(B10*1.1,5) -> 715 | E10: =CEILING(B10*1.15,5) -> 750 | F10: 1250 | G10: =(E10-B10)/B10 -> 0.15384615 | H10: =F10-E10 -> 500
A11: HC-019 | B11: 500 | D11: =CEILING(B11*1.1,5) -> 550 | E11: =CEILING(B11*1.15,5) -> 575 | F11: 990 | G11: =(E11-B11)/B11 -> 0.15 | H11: =F11-E11 -> 415
A12: HC-020 | B12: 650 | D12: =CEILING(B12*1.1,5) -> 715 | E12: =CEILING(B12*1.15,5) -> 750 | F12: 990 | G12: =(E12-B12)/B12 -> 0.15384615 | H12: =F12-E12 -> 240
A13: HD-003 | B13: 900 | D13: =CEILING(B13*1.1,5) -> 990 | E13: =CEILING(B13*1.15,5) -> 1035 | F13: 1250 | G13: =(E13-B13)/B13 -> 0.15 | H13: =F13-E13 -> 215
A14: HD-002 | B14: 520 | D14: =CEILING(B14*1.1,5) -> 575 | E14: =CEILING(B14*1.15,5) -> 600 | F14: 750 | G14: =(E14-B14)/B14 -> 0.15384615 | H14: =F14-E14 -> 150
... A17: A-041 | B17: 95 | D17: =CEILING(B17*1.1,5) -> 105 | E17: =CEILING(B17*1.15,5) -> 110 | F17: 125 | G17: =(E17-B17)/B17 -> 0.15789474 | H17: =F17-E17 -> 15
A18: VAL-1919-01 | B18: 400 | C18: 65 | D18: =CEILING(B18*1.1,5) -> 440 | E18: =CEILING(B18*1.15,5) -> 460 | F18: 499 | G18: =(E18-B18)/B18 -> 0.15 | H18: =F18-E18 -> 39
A19: VAL-1919-06 | B19: 400 | C19: 65 | D19: =CEILING(B19*1.1,5) -> 440 | E19: =CEILING(B19*1.15,5) -> 460 | F19: 499 | G19: =(E19-B19)/B19 -> 0.15 | H19: =F19-E19 -> 39
A20: VAL-1919-02 | B20: 400 | C20: 65 | D20: =CEILING(B20*1.1,5) -> 440 | E20: =CEILING(B20*1.15,5) -> 460 | F20: 499 | G20: =(E20-B20)/B20 -> 0.15 | H20: =F20-E20 -> 39
A21: VAL-2208-01 | B21: 330 | C21: 65 | D21: =CEILING(B21*1.1,5) -> 365 | E21: =CEILING(B21*1.15,5) -> 380 | F21: 400 | G21: =(E21-B21)/B21 -> 0.15151515 | H21: =F21-E21 -> 20
A22: HT-002 | B22: 600 | C22: 80 | D22: =CEILING(B22*1.1,5) -> 660 | E22: =CEILING(B22*1.15,5) -> 690 | F22: 750 | G22: =(E22-B22)/B22 -> 0.15 | H22: =F22-E22 -> 60
A23: PKY-2233 | B23: 1450 | D23: =CEILING(B23*1.1,5) -> 1595 | E23: =CEILING(B23*1.15,5) -> 1670 | F23: 1800 | G23: =(E23-B23)/B23 -> 0.15172414 | H23: =F23-E23 -> 130
A24: PKY-2235 | B24: 1800 | D24: =CEILING(B24*1.1,5) -> 1980 | E24: =CEILING(B24*1.15,5) -> 2070 | F24: 2400 | G24: =(E24-B24)/B24 -> 0.15 | H24: =F24-E24 -> 330
A25: XJ-200 | B25: 2350 | D25: =CEILING(B25*1.1,5) -> 2585 | E25: =CEILING(B25*1.15,5) -> 2705 | F25: 2800 | G25: =(E25-B25)/B25 -> 0.15106383 | H25: =F25-E25 -> 95
A26: XB-707 | B26: 2500 | D26: =CEILING(B26*1.1,5) -> 2750 | E26: =CEILING(B26*1.15,5) -> 2875 | F26: =MROUND((B26*20%)+B26,5) -> 3000 | G26: =(E26-B26)/B26 -> 0.15 | H26: =F26-E26 -> 125
A27: SM-01 | B27: 15000 | D27: =CEILING(B27*1.1,5) -> 16500 | E27: =CEILING(B27*1.15,5) -> 17250 | F27: =MROUND((B27*20%)+B27,5) -> 18000 | G27: =(E27-B27)/B27 -> 0.15 | H27: =F27-E27 -> 750
A28: T-21 | B28: 1250 | D28: =CEILING(B28*1.1,5) -> 1375 | E28: =CEILING(B28*1.15,5) -> 1440 | F28: 1450 | G28: =(E28-B28)/B28 -> 0.152 | H28: =F28-E28 -> 10
A29: HL-910/A | B29: 200 | D29: =CEILING(B29*1.1,5) -> 220 | E29: =CEILING(B29*1.15,5) -> 230 | F29: 350 | G29: =(E29-B29)/B29 -> 0.15 | H29: =F29-E29 -> 120
A30: HL-922/A | B30: 250 | D30: =CEILING(B30*1.1,5) -> 275 | E30: =CEILING(B30*1.15,5) -> 290 | F30: 370 | G30: =(E30-B30)/B30 -> 0.16 | H30: =F30-E30 -> 80
A31: VAL-5/B | B31: 600 | D31: =CEILING(B31*1.1,5) -> 660 | E31: =CEILING(B31*1.15,5) -> 690 | F31: 900 | G31: =(E31-B31)/B31 -> 0.15 | H31: =F31-E31 -> 210
A32: VAL-9/A | B32: 1200 | D32: =CEILING(B32*1.1,5) -> 1320 | E32: =CEILING(B32*1.15,5) -> 1380 | F32: 2500 | G32: =(E32-B32)/B32 -> 0.15 | H32: =F32-E32 -> 1120
A33: JH-802 | B33: 528 | D33: =CEILING(B33*1.1,5) -> 585 | E33: =CEILING(B33*1.15,5) -> 610 | F33: 650 | G33: =(E33-B33)/B33 -> 0.15530303 | H33: =F33-E33 -> 40
A34: VAL-61 | B34: 290 | D34: =CEILING(B34*1.1,5) -> 320 | E34: =CEILING(B34*1.15,5) -> 335 | F34: 450 | G34: =(E34-B34)/B34 -> 0.15517241 | H34: =F34-E34 -> 115
A35: VAL-62 | B35: 305 | D35: =CEILING(B35*1.1,5) -> 340 | E35: =CEILING(B35*1.15,5) -> 355 | F35: 450 | G35: =(E35-B35)/B35 -> 0.16393443 | H35: =F35-E35 -> 95
A36: VAL-PA03-60 | B36: 350 | D36: =CEILING(B36*1.1,5) -> 385 | E36: =CEILING(B36*1.15,5) -> 405 | F36: 490 | G36: =(E36-B36)/B36 -> 0.15714286 | H36: =F36-E36 -> 85
A37: VAL-PA03-630 | B37: 360 | D37: =CEILING(B37*1.1,5) -> 400 | E37: =CEILING(B37*1.15,5) -> 415 | F37: 490 | G37: =(E37-B37)/B37 -> 0.15277778 | H37: =F37-E37 -> 75
A38: VAL-VT01-60 | B38: 750 | D38: =CEILING(B38*1.1,5) -> 825 | E38: =CEILING(B38*1.15,5) -> 865 | F38: 900 | G38: =(E38-B38)/B38 -> 0.15333333 | H38: =F38-E38 -> 35
A39: VAL-VT03-630F | B39: 750 | D39: =CEILING(B39*1.1,5) -> 825 | E39: =CEILING(B39*1.15,5) -> 865 | F39: 900 | G39: =(E39-B39)/B39 -> 0.15333333 | H39: =F39-E39 -> 35
... A123: GX-002 | B123: 70 | D123: =CEILING(B123*1.1,5) -> 80 | E123: =CEILING(B123*1.15,5) -> 85 | F123: 100 | G123: =(E123-B123)/B123 -> 0.21428571 | H123: =F123-E123 -> 15
A124: VAL-501/3 | B124: 18 | D124: =CEILING(B124*1.1,5) -> 20 | E124: =CEILING(B124*1.15,5) -> 25 | F124: =CEILING(B124*1.3,5) -> 25 | G124: =(E124-B124)/B124 -> 0.38888889 | H124: =F124-E124 -> 0
A125: PKY-1506 | B125: 16 | D125: =CEILING(B125*1.1,5) -> 20 | E125: =CEILING(B125*1.15,5) -> 20 | F125: 50 | G125: =(E125-B125)/B125 -> 0.25 | H125: =F125-E125 -> 30
...

Sheet data
A1: รหัสสินค้า | B1: สี | C1: ออฟชั่น | D1: ชื่อสินค้า | E1: รายละเอียดสินค้า | F1: แบรนด์ | G1: หมวด | H1: หมวดย่อย | I1: ซัพพลายเออร์ | J1: ต้นทุน | K1: ส่ง | L1: ตัวแทน | M1: ลดพิเศษ | N1: ปลีก | O1: หน้าเว็บ | P1: สต๊อก | Q1: ลดราคา | R1: ร่วมโปร | S1: ขายตัวแทน | T1: ขายหน้าเว็บ | U1: SKU | V1: บาร์โคด
A2: GAD-001 | D2: กู๊ด ออล เดย์ | E2: <p>GOOD ALL DAY:GENTLEMAN POMADE</p> <p>สีฟ้า กู๊ด ออล เดย์ เจนเทิลแมนโพเมด ปริมาณ 80 g.</p> <p>&nbsp; &nbsp; &nbsp; &nbsp;โพเมดจัดเเต่งทรงผม สูตร water based ให้ผมอยู่ทรงนานตลอดทั้งวัน ล้างออกง่าย จัดเเต่งทรงผม</p> <p>ได้หลายสไตล์ ทั้งแนววินเทจหรือปฟชั้น เพิ่มความมั่นใจหมดห่วงเรื่องทรงผมตลอดทั้งวัน</p> <p>&nbsp;</p> <p>วิธีใช้. นำโพเมดมาถูบนฝ่ามือให้อ่อนตัวลงเเล้วใช้จัดเเต่งทรงผมตามต้องการ</p> <p>warning: ควรใช้กับเส้นผมเท่านั้น</p> <p><br /><br /></p> | F2: GOOD ALL DAY | G2: Grooming - ผลิตภัณพ์จัดแต่งทรงผมและหนวด | H2: Hair Styling (จัดแต่งทรงผมผู้ชาย) | I2: บริษัท พันธ์วาดี จำกัด | J2: 190 | K2: 99 | L2: 250 | M2: 200 | N2: 390 | O2: 540 | P2: 85 | S2: 1 | T2: 1 | V2: 8858890715045
A3: GAD-002 | D3: กู๊ด ออล เดย์ ไฟเบอร์ แว็กซ์ | E3: <p>GOOD ALL DAY: Gentleman Fiber Wax สีเหลือง</p> <p>กู๊ด ออล เดย์ เจนเทิลแมนไฟเบอร์ แว๊ก 80 g.</p> <p>&nbsp; &nbsp; &nbsp; แว๊กซ์จัดแต่งทรงผม สูตร FIBER ช่วยให้ผมอยู่ทรงยาวนานตลอดทั้งวัน ล้างออกง่าย</p> <p>จัดแต่งทรงผมได้หลากหลายสไตล์ ทั้งแนววินเทจหรือปฟชั้น เพิ่มความมั่นใจหมดห่วงเรื่อง</p> <p>ทรงผม ตลอดทั้งวัน</p> <p>&nbsp;</p> <p>วิธีใช้: นำเเว็กซ์มาถูบนฝ่ามือให้อ่อนตัวลงแล้วใช้จัดเเต่งทรงผมตามต้องการ</p> <p>warning: ควรใช้กับเส้นผมเท่านั้น</p> | F3: GOOD ALL DAY | G3: Grooming - ผลิตภัณพ์จัดแต่งทรงผมและหนวด | H3: Hair Styling (จัดแต่งทรงผมผู้ชาย) | I3: บริษัท พันธ์วาดี จำกัด | J3: 150 | K3: 99 | L3: 200 | M3: 200 | N3: 290 | O3: 450 | P3: 79 | R3: 1 | S3: 1 | T3: 1 | V3: 8858890715052
A4: GAD-003 | D4: กู๊ด ออล เดย์ แบล็ค เคลย์ | E4: <p>GOOD ALL DAY: Gentleman All Black Clay สีดำ</p> <p>กู๊ด ออล เดย์ เจนเทิลแมนออลแบล็คเครย์ 80 ml.</p> <p>&nbsp; &nbsp; &nbsp; &nbsp; &nbsp;ดินน้ำมันแต่งผม เพิ่มแท๊กซ์เจอร์และให้ลุคทรงผมด้านไม่เงา ผมอยู่ทรงนานตลอดทั้งวัน</p> <p>ล้างออกง่าย จัดแต่งทรงผมได้หลากหลายสไตล์ทั้งแนววืนเทจและแฟชั่น เพิ่มความมั่นใจหมด</p> <p>ห่วงเรื่องผมตลอดทั้งวัน</p> <p>&nbsp;</p> <p>วิธีใช้: นำเครย์มาถูบนฝ่ามือให้อ่อนตัวลงเเล้วใช้จัดเเต่งทรงผมตามต้องการ</p> <p>warning: ควรใช้กับเส้นผมเท่านั้น</p> | F4: GOOD ALL DAY | G4: Grooming - ผลิตภัณพ์จัดแต่งทรงผมและหนวด | H4: Hair Styling (จัดแต่งทรงผมผู้ชาย) | I4: บริษัท พันธ์วาดี จำกัด | J4: 150 | K4: 99 | L4: 290 | M4: 170 | N4: 320 | O4: 540 | P4: 42 | S4: 1 | T4: 1 | V4: 8858890715069
A5: BB-702 | D5: บาร์เบอร์ เบรน เท็คเจอร์ & วอลลุ่ม แฮร์ สเปรย์ BB-702 | E5: <p>BARBER BRAIN Texture &amp; Volume Hair Spray&nbsp;</p> <p>บาร์เบอร์ เบรน เท็กซ์เจอร์ &amp; วอลลุ่ม แฮร์ สเปรย์</p> <p>ปริมาณ&nbsp;200 ml.</p> <p>&nbsp;</p> <p>คุณสมบัติ:</p> <p>&nbsp; &nbsp; &nbsp; &nbsp; &nbsp;✔︎ เพิ่มเท็กซ์เจอร์และวอลลุ่มให้เส้นผม</p> <p>&nbsp; &nbsp; &nbsp; &nbsp; &nbsp;✔︎ ช่วยให้การไดร์ยกโคนผมง่ายขึ้น</p> <p>&nbsp; &nbsp; &nbsp; &nbsp; &nbsp;✔︎ ทรงผมเป็นธรรมชาติอย่างมีสไตล์</p> | F5: Barber Brain | G5: Grooming - ผลิตภัณพ์จัดแต่งทรงผมและหนวด | H5: Hair Styling (จัดแต่งทรงผมผู้ชาย) | I5: บริษัท พันธ์วาดี จำกัด | J5: 99 | K5: 99 | L5: 179 | M5: 180 | N5: 199 | O5: 199 | P5: 231 | S5: 1 | T5: 1 | V5: 8858890717025
A6: BB-108 | D6: ปัตตาเลี่ยนไร้สาย BB-108 แถมหวีรองซอย BB-106-06 | E6: <p class="p1">&ldquo;Barber Brain Wireless Hair clipper the Black Beast series II&rdquo;</p> <p class="p2"><span class="s1">&ldquo;</span>บาร์เบอร์เบรน ปัตตาเลี่ยนไร้สาย เดอะ แบล็ค บีซท รุ่น<span class="s1"> 2&rdquo;</span></p> <p class="p2">&nbsp;</p> <p class="p1">คุณสมบัติ</p> <p class="p1"><span class="s2">กำลังไฟ</span>&nbsp;220V 50Hz 6w</p> <p class="p2">ใบมีดฟันคู่<span class="s1">&nbsp;micro teeth blade&nbsp;</span>หรือที่ช่างผมเรียกว่าฟันเฟด</p> <p class="p2">ปรับระดับฟันได้ถึง<span class="s1">&nbsp;4&nbsp;</span>ขั้น</p> <p class="p2">ความเร็วรอบมอเตอร์ไฟฟ้า<span class="s1">&nbsp;6,000 RPM</span></p> <p class="p2">แบตลิเที่ยม<span class="s1">&nbsp;2,600 mAh</span></p> <p class="p2">&nbsp;</p> <p class="p2">&nbsp;</p> | F6: Barber Brain | G6: Electrical Equipment - อุปกรณ์ไฟฟ้า | H6: ปัตตาเลี่ยนไร้สาย | I6: บริษัท พันธ์วาดี จำกัด | J6: 945 | K6: 999 | L6: 1130 | M6: 1200 | N6: 1450 | O6: 1450 | P6: 501 | R6: 1 | S6: 1 | T6: 1 | V6: 8588890721172
A7: BB-503 | D7: บาร์เบอร์ เบรน ผลิตภัณฑ์จัดแต่งทรงผม โพเมด สูตรเงา รุ่น BB-503 | E7: <p>BARBER BRAIN Glue Gel เจลจัดแต่งทรงผม ขนาด 80g.</p> <p>คุณสมบัติ:<br />&nbsp; &nbsp; &nbsp; &nbsp; &nbsp; &nbsp; เจลจัดแต่งทรงผม สำหรับผู้ที่ชื่นชอบทรงผมลุคเนี๊ยบ เท่ๆ หรือทรงผมแนวย้อนยุควินเทจ<br />โดยเฉพาะ ให้ทรงผมอยู่ทรงทั้งวันพร้อมให้ความเงาสูง ช่วยให้คุณจัดแต่งทรงผมได้หลากหลายสไตล์ <br />ล้างทำความสะอาดง่ายไม่เหนียวเหนอะหนะ และไม่ทำให้เกิดขุย <br />&nbsp; &nbsp; &nbsp;✔︎ ใช้สำหรับจัดแต่งทรงผมชาย ได้หลายทางหรือแม้แต่หวีเรียบ <br />&nbsp; &nbsp; &nbsp;✔︎ อยู่ทรงทั้งวัน และปรับแต่งทรงผมได้ตลอดทั้งวัน <br />&nbsp; &nbsp; &nbsp;✔︎ หล่อ ดูดี มีชีวิตชีวา <br />&nbsp; &nbsp; &nbsp;✔︎ เนื้อเจลเป็นเนื้อแบบกลูเจลทำให้ง่ายต่อการเกลี่ยจัดแต่งทรงผมแลุอยู่ติดทนยาวนานยิ่งขึ้น</p> <p><br /> <br />วิธีใช้: <br /> &nbsp; &nbsp; &nbsp; &nbsp; &nbsp; &nbsp;&nbsp;สามารถทำได้ด้วยตนเอง เพียงแค่ควักเนื้อครีม ปริมาณ 1 ข้อนิ้ว แล้วทาลงบนบริเวณที่<br />ต้องการจะจัดแต่งเส้นผมให้อยู่ทรง</p> <p><br />Warning*สำหรับใช้กับเส้นผมเท่านั้น <br />โปรดเก็บไว้ในที่ร่มและพ้นมือเด็ก ห้ามใช้กับเด็กที่มีอายุต่ำกว่า 3 ขวบ และระวังอย่าให้เข้าตา</p> <p>..........................................................................</p> <p class="p1">&nbsp;</p> | F7: Barber Brain | G7: Grooming - ผลิตภัณพ์จัดแต่งทรงผมและหนวด | H7: Hair Styling (จัดแต่งทรงผมผู้ชาย) | I7: บริษัท พันธ์วาดี จำกัด | J7: 150 | K7: 99 | L7: 215 | M7: 165 | N7: 240 | O7: 240 | P7: 87 | S7: 1 | T7: 1 | V7: 8858890715038
A8: PK-0529 | B8: 01-BLACK | D8: กระจกเหลี่ยม | E8: <p>กระจกเหลี่ยม <br />มีขนาดถึงปลายด้ามจับ 31*22.5 ซม. <br />ขนาดไม่รวมด้ามจับ 20ซม. หนา 1ซม.</p> <p>คุณสมบัติ: <br />✔︎ กระจกเหลี่ยม บาร์เบอร์เบรน <br />✔︎ ใช้สำหรับส่องให้ลูกค้าสามารถเห็นทรงผมด้านหลังหรือสามารถใช้ส่องเวลาตัดผมด้วยตนเอง <br />✔︎ วัสดุดีมีคุณภาพ แข็งแรงทนทาน <br />✔︎ กระจกไม่มัว ไม่หลอกตาแน่นอน<br /> ..........................................................................</p> <p>&nbsp;</p> | F8: VALENTE | G8: Other Equipment - อุปกรณ์อื่นๆ | H8: กระจก | I8: บริษัท พันธ์วาดี จำกัด | J8: 70 | K8: 0 | L8: 85 | M8: 0 | N8: 100 | O8: 150 | P8: 7 | R8: 1 | S8: 1 | T8: 1 | V8: 8858890790233
A9: PKY-1577 | D9: กรรไกรตัดซอย 5.5นิ้ว | E9: <p>ในชุดมีทั้ง <br />1. กรรไกรซอย+กรรไกรตัดผม ขนาด 5.5 นิ้ว<br />2. ฟรีกระเป๋าใส่กรรไกร</p> <p>คุณสมบัติ: <br />✔︎ ชุดกรรไกรตัด+ซอย <br />✔︎ น้ำหนักเบา จับถนัดมือ <br />✔︎ มียางกันกระแทก <br />✔︎ ตัวกรรไกรทำจากเหล็กคุณภาพสูง <br />✔︎ พร้อมใช้งานได้ทันทีโดยไม่ต้องลับคมกรรไกร <br />✔︎ ด้วยคุณภาพของวัสดุชั้นดี ให้ความคมสูงมาก <br />✔︎ สัมผัสลื่น คม โลหะคุณภาพดี<br />✔︎ ทำจากวัสดุชั้นดีแข็งแรงทนทาน</p> <p>วิธีใช้: <br />✂ กรรไกรตัด ใช้ตัดผมให้สั้นลง บางทีก็ใช้ตัดให้ผมบางลงได้ ขึ้นอยู่กับวิธีการตัด <br />✂ กรรไกรซอย(ฟันปลา) ใช้ซอยผมให้บางลง ขนาดความยาวเท่าเดิม <br />**สามารถดูวิธีใช้เพิ่มเติมได้ที่ QR code บนกล่อง</p> <p>..........................................................................</p> <p>&nbsp;</p> | F9: VALENTE | G9: Hair Scissors - กรรไกรตัดซอย | H9: สินค้าแบบเซต | I9: บริษัท พันธ์วาดี จำกัด | J9: 325 | K9: 0 | L9: 0 | M9: 0 | N9: 570 | O9: 700 | P9: 0 | T9: 1 | V9: 8858890760946
A10: OY-601 | B10: 10-PINK | D10: หมอนรองมือ | E10: <p>หมอนรองมือ</p> <p>คุณสมบัติ: <br />✔︎ วัสดุทำจาก PVC หรือพลาสติกแปรรูป <br />✔︎ ขนาด กว้าง 9.5 ซม. ยาว 29.5 ซม. สูง 6 ซม. <br />✔︎ ใช้สำหรับรองมือขณะทำเล็บ <br />✔︎ ป้องกันอาการเมื่อยข้อมือของลูกค้า <br />✔︎ มี4สี สีชมพูเข้ม / ชมพูอ่อน / สีม่วง / สีส้ม</p> <p><br /><br /></p> | F10: VALENTE | G10: Manicure and Pedicure - สปามือและเท้า | H10: Nail Tools (อุปกรณ์ตกแต่ง) | I10: บริษัท พันธ์วาดี จำกัด | J10: 83 | K10: 0 | L10: 0 | M10: 0 | N10: 99 | O10: 200 | P10: 5 | R10: 1 | S10: 1 | T10: 1 | V10: 8858890732264
A11: OY-601 | B11: 13-ORANGE | D11: หมอนรองมือ | E11: <p>หมอนรองมือ</p> <p>คุณสมบัติ: <br />✔︎ วัสดุทำจาก PVC หรือพลาสติกแปรรูป <br />✔︎ ขนาด กว้าง 9.5 ซม. ยาว 29.5 ซม. สูง 6 ซม. <br />✔︎ ใช้สำหรับรองมือขณะทำเล็บ <br />✔︎ ป้องกันอาการเมื่อยข้อมือของลูกค้า <br />✔︎ มี4สี สีชมพูเข้ม / ชมพูอ่อน / สีม่วง / สีส้ม</p> <p><br /><br /></p> | F11: VALENTE | G11: Manicure and Pedicure - สปามือและเท้า | H11: Nail Tools (อุปกรณ์ตกแต่ง) | I11: บริษัท พันธ์วาดี จำกัด | J11: 83 | K11: 0 | L11: 0 | M11: 0 | N11: 99 | O11: 200 | P11: 3 | R11: 1 | S11: 1 | T11: 1 | V11: 8858890732264
A12: OY-601 | B12: 17-LIGHT PINK | D12: หมอนรองมือ | E12: <p>หมอนรองมือ</p> <p>คุณสมบัติ: <br />✔︎ วัสดุทำจาก PVC หรือพลาสติกแปรรูป <br />✔︎ ขนาด กว้าง 9.5 ซม. ยาว 29.5 ซม. สูง 6 ซม. <br />✔︎ ใช้สำหรับรองมือขณะทำเล็บ <br />✔︎ ป้องกันอาการเมื่อยข้อมือของลูกค้า <br />✔︎ มี4สี สีชมพูเข้ม / ชมพูอ่อน / สีม่วง / สีส้ม</p> <p><br /><br /></p> | F12: VALENTE | G12: Manicure and Pedicure - สปามือและเท้า | H12: Nail Tools (อุปกรณ์ตกแต่ง) | I12: บริษัท พันธ์วาดี จำกัด | J12: 83 | K12: 0 | L12: 0 | M12: 0 | N12: 99 | O12: 200 | P12: 2 | R12: 1 | S12: 1 | T12: 1 | V12: 8858890732264
A13: VAL-684 | D13: แปรงปัดผม VALENTE HAIR BRUSH VAL-684/C | E13: <p>ใช้ปัดหนวด ปัดเส้นผม ขนาดแปรงจับถนัดมือ ขนทำมาจากขนไนลอน ใช้ง่าย</p> <p>คุณสมบัติ: <br />✔︎ ขนไนลอนชั้นดี ใช้ปัดเศษผม <br />✔︎ ขนแปรงไม่แข็งมากและไม่อ่อนจนเกินไป <br />✔︎ ทนทาน ขนไม่หลุดง่าย ไม่ระคายเคือง <br />✔︎ ด้ามจับถนัดเหมาะมือ</p> <p>วิธีใช้: <br />ใช้หลังการตัดผม ปัดเศษผมเพื่อเก็บรายละเอียด และความสะอาด<br />*เหมาะสำหรับร้านบาร์เบอร์และซาลอน*<br /> ..........................................................................</p> | F13: VALENTE | G13: Comb and Brush - หวีและแปรง | H13: แปรงปัดเศษผม | I13: บริษัท พันธ์วาดี จำกัด | J13: 55 | K13: 55 | L13: 70 | M13: 65 | N13: 85 | O13: 100 | P13: 278 | R13: 1 | S13: 1 | T13: 1 | V13: 8858890794798
A14: VAL-217 | B14: 01-BLACK | D14: วาเลนเต้ มีดโกนหนวดแบบพับ 0.030g. รหัสสินค้า VAL-217 | E14: <p>คุณสมบัติ: <br /> ด้ามมีดโกน แบบพับได้ สีครีม,สีดำ <br /> ความยาวทั้งหมดประมาน 23.5 ซม. <br /> ใบมีดหักครึ่ง ใบมีดสองคม</p> <p>✔︎ วัสดุทนทาน <br />✔︎ น้ำหนักเบาใช้งานง่าย <br />✔︎ เปลี่ยนใบมีดได้ <br />✔︎ ด้ามมีดโกน กันจอน โกนหนวด ตัดผมหางเหล็ก</p> <p>..........................................................................</p> <p>&nbsp;</p> <p>&nbsp;</p> | F14: VALENTE | G14: Other Equipment - อุปกรณ์อื่นๆ | H14: ด้ามมีดโกน | I14: บริษัท พันธ์วาดี จำกัด | J14: 25 | K14: 0 | L14: 35 | M14: 0 | N14: 60 | O14: 100 | P14: 11 | R14: 1 | S14: 1 | T14: 1 | V14: 885889079379102
A15: VAL-217 | B15: 14-CREAM | D15: วาเลนเต้ มีดโกนหนวดแบบพับ 0.030g. รหัสสินค้า VAL-217 | E15: <p>คุณสมบัติ: <br /> ด้ามมีดโกน แบบพับได้ สีครีม,สีดำ <br /> ความยาวทั้งหมดประมาน 23.5 ซม. <br /> ใบมีดหักครึ่ง ใบมีดสองคม</p> <p>✔︎ วัสดุทนทาน <br />✔︎ น้ำหนักเบาใช้งานง่าย <br />✔︎ เปลี่ยนใบมีดได้ <br />✔︎ ด้ามมีดโกน กันจอน โกนหนวด ตัดผมหางเหล็ก</p> <p>..........................................................................</p> <p>&nbsp;</p> <p>&nbsp;</p> | F15: VALENTE | G15: Other Equipment - อุปกรณ์อื่นๆ | H15: ด้ามมีดโกน | I15: บริษัท พันธ์วาดี จำกัด | J15: 25 | K15: 0 | L15: 35 | M15: 0 | N15: 60 | O15: 100 | P15: 16 | R15: 1 | S15: 1 | T15: 1 | V15: 885889079379101
A16: VAL-217 | B16: 14-CREAM | C16: SIZE: S | D16: วาเลนเต้ มีดโกนหนวดแบบพับ 0.030g. รหัสสินค้า VAL-217 | E16: <p>คุณสมบัติ: <br /> ด้ามมีดโกน แบบพับได้ สีครีม,สีดำ <br /> ความยาวทั้งหมดประมาน 23.5 ซม. <br /> ใบมีดหักครึ่ง ใบมีดสองคม</p> <p>✔︎ วัสดุทนทาน <br />✔︎ น้ำหนักเบาใช้งานง่าย <br />✔︎ เปลี่ยนใบมีดได้ <br />✔︎ ด้ามมีดโกน กันจอน โกนหนวด ตัดผมหางเหล็ก</p> <p>..........................................................................</p> <p>&nbsp;</p> <p>&nbsp;</p> | F16: VALENTE | G16: Other Equipment - อุปกรณ์อื่นๆ | H16: ด้ามมีดโกน | I16: บริษัท พันธ์วาดี จำกัด | J16: 25 | K16: 0 | L16: 35 | M16: 0 | N16: 60 | O16: 100 | P16: 0 | R16: 1 | S16: 1 | T16: 1 | V16: 885889079379101
